Workbook
Name _1枚目: #REF!
Name _1枚目: #REF!
Name _1枚目: [2]納入先!#REF!
Name _1枚目: [3]納入先!#REF!
Name _1枚目: #REF!
Name _2枚目: #REF!
Name _2枚目: #REF!
Name _2枚目: [4]UMG受領資料_注文!#REF!
Name _2枚目: #REF!
Name _2枚目: #REF!
Name _3枚目: #REF!
Name _3枚目: #REF!
Name _3枚目: [2]注文確認!#REF!
Name _3枚目: [3]注文確認!#REF!
Name _3枚目: #REF!
Name _4枚目: #REF!
Name _4枚目: #REF!
Name _4枚目: #REF!
Name _4枚目: #REF!
Name _4枚目: #REF!
Name a: #REF!
Name a: #REF!
Name a: #REF!
Name AA: #REF!
Name AA: #REF!
Name AA: #REF!
Name AA: #REF!
Name AA: #REF!
Name b: #REF!
Name b: #REF!
Name b: #REF!
Name B_下: #REF!
Name B_下: #REF!
Name B_下: '[10]営業系PG管理表 (テストフェーズ別)'!#REF!
Name B_下: '[10]営業系PG管理表 (テストフェーズ別)'!#REF!
Name B_下: #REF!
Name B_上: #REF!
Name B_上: #REF!
Name B_上: '[10]営業系PG管理表 (テストフェーズ別)'!#REF!
Name B_上: '[10]営業系PG管理表 (テストフェーズ別)'!#REF!
Name B_上: #REF!
Name CSV項目編集仕様: #REF!
Name CSV項目編集仕様: #REF!
Name dd: #REF!
Name dd: #REF!
Name dd: #REF!
Name DS_下: #REF!
Name DS_下: #REF!
Name DS_下: '[10]営業系PG管理表 (テストフェーズ別)'!#REF!
Name DS_下: '[10]営業系PG管理表 (テストフェーズ別)'!#REF!
Name DS_下: #REF!
Name DS_上: #REF!
Name DS_上: #REF!
Name DS_上: '[10]営業系PG管理表 (テストフェーズ別)'!#REF!
Name DS_上: '[10]営業系PG管理表 (テストフェーズ別)'!#REF!
Name DS_上: #REF!
Name ＤＳ担当: #REF!
Name ＤＳ担当: #REF!
Name GUI名称: #REF!
Name GUI名称: #REF!

Sheet  cover
C2: Inabata & Co., Ltd.
A8: EDI system
A10: Batch processing design document
A13: Techno UMG_Payment and payment details
A17: - Ver.2.00 -
A22: 45842
A24: Fujitsu Limited
V28: approval | AA28: create
AA29: 45842
AA30: FJ) Kunimitsu

Sheet  Change history
A1: Inabata & Co., Ltd. | F1: Batch processing design document | T1: Account Name | AH1: Customer abbreviation ID | AS1: Category Name | BB1: Author | BF1: Creation date | BJ1: Updated by | BN1: Update date
T3: Techno UMG | AH3: TUG | AS3: Payment and payment details | BB3: FJ) Kunimitsu | BF3: 45842
B7: No. | D7: Version | H7: Change Date | L7: Changed by | O7: classification | Q7: Change Control Number | U7: Changes | AF7: Changes | AY7: remarks
B8: =ROW()-7 -> 1 | D8: 2.00 | H8: 45842 | L8: FJ Kunimitsu | O8: New | Q8: R60795 | AF8: Create New | AY8: EDI middleware migration support
B9: =ROW()-7 -> 2
B10: =ROW()-7 -> 3
B11: =ROW()-7 -> 4
B12: =ROW()-7 -> 5
B13: =ROW()-7 -> 6
B14: =ROW()-7 -> 7
B15: =ROW()-7 -> 8
B16: =ROW()-7 -> 9
B17: =ROW()-7 -> 10
B18: =ROW()-7 -> 11
B19: =ROW()-7 -> 12
B20: =ROW()-7 -> 13
... B52: =ROW()-7 -> 45

Sheet  1. Transmission and reception information
A1: Inabata & Co., Ltd. | E1: Batch processing design document | O1: Account Name | X1: Customer abbreviation ID | AC1: Category Name | AG1: Author | AJ1: Creation date | AM1: Updated by | AP1: Update date
O3: =Change history!T3 -> Techno UMG | X3: =Change history!AH3 -> TUG | AC3: =Change history!AS3 -> Payment and payment details | AG3: =Change history!BB3 -> FJ) Kunimitsu | AJ3: =Change history!BF3 -> 45842
B6: ① List of sent and received files
K7: S: Start, H: Header, B: Body, T: Trailer, E: End
C8: No. | D8: category | K8: Format Type | R8: File structure | W8: 0Data transmission status
C9: 1 | D9: Payment details | K9: JPCA | R9: Heart, Body, and Teeth | W9: Nothing
B11: ②How to read the data
C12: Payment details data | V12: H: Header | AD12: *
C13: B: Body | V13: B: Body
C14: B: Body | V14: B: Body
C15: B: Body | V15: B: Body
V16: T: Trailer | AD16: *
Q18: File structure | V18: First record: Header, Body, Last record: Trailer
B19: ③Extraction conditions | V19: (*Added by NTS processing)
C21: Please refer to the "2. Function" sheet.
B23: 4. Header/trailer editing
C24: Granted in batches when converting to CII.
B26: ⑤0 data transmission specifications
C28: none

Sheet  2. Function
A1: Inabata & Co., Ltd. | E1: Batch processing design document | O1: Account Name | X1: Customer abbreviation ID | AC1: Category Name | AG1: Author | AJ1: Creation date | AM1: Updated by | AP1: Update date
O3: =Change history!T3 -> Techno UMG | X3: =Change history!AH3 -> TUG | AC3: =Change history!AS3 -> Payment and payment details | AG3: =Change history!BB3 -> FJ) Kunimitsu | AJ3: =Change history!BF3 -> 45842
B6: ①Purpose
C8: ・In Common Process_EDI Send_Payment_Data Extraction, import the linked file (TUGA140S02001) and create a payment details file for Techno UMG.
B10: ② Functionality overview
C12: ・Import the linked file, extract the data to be sent, and check the number of items.
C13: ・If the number of data items to be sent is not 0, create a file to send to the business partner.
C14: - Call mplt_CMN_EDI sending DB_payment update 2 and update the EDI sending status type and processing receipt number of EDI sending DB_payment.
B17: ③ Input/output information
C19: [input]
C20: Table name or file name | M20: Extraction conditions | AE20: Purpose of use
C21: Linked files | M21: EDI server: /PRD/Temp/TUGA140S02001 (created by common processing) | AE21: Extracting data to be sent
C22: 3. INPUT file layout (B)
C25: [output]
C26: Table name or file name | M26: Update conditions, extraction conditions | AE26: Purpose of use
C27: Sending file (payment details) | M27: Created based on the following extraction conditions. | AE27: Creating files to send to business partners
C28: (4. OUTPUT file layout (B)) | M28: Linked file.Delete category = "0" (enabled) and
M29: Linked file.Transmission data deletion category = "0" (transmission target) and
M30: Linked file.EDI_Current payment amount<>0
M32: The summary key for the sending file (payment) is as follows:
N33: Linked file. Supplier code (top 6)
N34: Linked file.Denomination
N35: Linked file. Head office/branch code
N36: Linked file. Supplier code (bottom 4)
N37: Linked file.Payment date
C39: EDI Send DB_Payment | M39: Updated based on the following renewal conditions: | AE39: Set the processed flag
M40: Send Sequence No. = Linked File.Send Sequence No. | AE40: EDI_Transmission status type="3" (Processed)
AE41: Processing receipt number = Linked file.Processing receipt number
B45: ④Function details
C47: (1) Importing linked files
D49: Import the linked file "TUGA140S02001" created in the common process.
D50: →File path: /EDI Server/PRD/Temp/TUGA140S02001
C53: (2) Creating data to be sent
D55: ① Obtain the data to be sent from the linked file.
D57: Extraction conditions:
E58: ・Linked file.Delete category = "0" (enabled)
E59: ・Linked file.Transmission data deletion classification = "0" (transmission target)
E60: ・Linked file.Payment・EDI_Current payment amount<>0
D62: ②If there is data to be sent, create a file to send to the business partner.
E63: 1 | F63: Editing data by recipient
...

Sheet  3. INPUT file layout (B)
A6: ■ | B6: INPUT file layout | E6: Record length | G6: =SUM(G10:G37) -> 4241 | H6: Character encoding | J6: SJIS
A7: [Body Record]
B8: item | H8: decimal | I8: decimal point | J8: PAC/ | K8: Shift presence/absence | L8: start
A9: No. | B9: group | C9: Item name (Japanese name) | D9: Item name (English name) | E9: Character encoding | F9: Type | G9: number of digits | H9: number of digits | I9: presence or absence | J9: UNPAC | L9: position | M9: remarks
A10: =ROW()-9 -> 1 | C10: Transmission Sequence No. | D10: SND_SEQ_NO | F10: Half-width alphanumeric characters | G10: 10 | L10: 1
A11: =ROW()-9 -> 2 | C11: Data Exchange ID | D11: DATA_KOKAN_ID | F11: Half-width alphanumeric characters | G11: 6 | L11: =L10+G10 -> 11
A12: =ROW()-9 -> 3 | C12: EDI_Function Category Code | D12: EDI_KINO_CATEGORY_CD | F12: Half-width alphanumeric characters | G12: 4 | L12: =L11+G11 -> 17
A13: =ROW()-9 -> 4 | C13: Supplier Code | D13: SUP_CD | F13: Half-width numbers | G13: 14 | L13: =L12+G12 -> 21
A14: =ROW()-9 -> 5 | C14: Sales area | D14: HAN_KBN | F14: Half-width alphanumeric characters | G14: 3 | L14: =L13+G13 -> 35
A15: =ROW()-9 -> 6 | C15: Starting date | D15: KISAN_D | F15: Half-width alphanumeric characters | G15: 8 | L15: =L14+G14 -> 38
A16: =ROW()-9 -> 7 | C16: denomination | D16: KINSHU | F16: Half-width English characters | G16: 1 | L16: =L15+G15 -> 46
A17: =ROW()-9 -> 8 | C17: Head office/branch code | D17: HONSHITEN_CD | F17: Half-width numbers | G17: 1 | L17: =L16+G16 -> 47
A18: =ROW()-9 -> 9 | C18: Deadline | D18: SHIMEKIRI_YMD | F18: Date (year, month, day) | G18: 8 | L18: =L17+G17 -> 48
A19: =ROW()-9 -> 10 | C19: Maturity Date | D19: MANKI_D | F19: Half-width alphanumeric characters | G19: 8 | L19: =L18+G18 -> 56
A20: =ROW()-9 -> 11 | C20: Bank Code | D20: BANK_CD | F20: Half-width numbers | G20: 4 | L20: =L19+G19 -> 64
A21: =ROW()-9 -> 12 | C21: Branch code | D21: SHITEN_CD | F21: Half-width numbers | G21: 3 | L21: =L20+G20 -> 68
A22: =ROW()-9 -> 13 | C22: Bank name (kana) | D22: BANK_NMK | F22: Half-width characters | G22: 40 | L22: =L21+G21 -> 71
... A25: =ROW()-9 -> 16 | C25: Transfer account number | D25: FURIKOMI_KOZA_NO | F25: Half-width alphanumeric characters | G25: 7 | L25: =L24+G24 -> 152
A26: =ROW()-9 -> 17 | C26: EDI_Current payment amount | D26: EDI_KONKAI_PAY_GAKU | F26: Number | G26: 13 | H26: 0 | L26: =L25+G25 -> 159
A27: =ROW()-9 -> 18 | C27: Payment date | D27: PAY_YMD | F27: Date (year, month, day) | G27: 8 | L27: =L26+G26 -> 172
A28: =ROW()-9 -> 19 | C28: Transmission data deletion category | D28: SND_DATA_DEL_KBN | F28: Half-width numbers | G28: 1 | L28: =L27+G27 -> 180
A29: =ROW()-9 -> 20 | C29: Receive Sequence No. | D29: RCV_SEQ_NO | F29: Half-width alphanumeric characters | G29: 10 | L29: =L28+G28 -> 181
A30: =ROW()-9 -> 21 | C30: Processing receipt number | D30: FUNC_UKETSUKE_NO | F30: Number | G30: 10 | L30: =L29+G29 -> 191
A31: =ROW()-9 -> 22 | C31: Deletion category | D31: DEL_KBN | F31: Half-width numbers | G31: 1 | L31: =L30+G30 -> 201
A32: =ROW()-9 -> 23 | C32: Receive sequence No. 2 | D32: RCV_SEQ_NO_2 | F32: Half-width characters | G32: 10 | L32: =L31+G31 -> 202
A33: =ROW()-9 -> 24 | C33: Confirmed Purchase Responsible Organization Code (old) | D33: CONFIRM_SIR_SKNIN_SSHK_CD_OLD | F33: Half-width alphanumeric characters | G33: 5 | L33: =L32+G32 -> 212
A34: =ROW()-9 -> 25 | C34: JPCA_EDI billed amount | D34: JPCA_EDI_SEIKYU_GAKU | F34: Number | G34: 13 | H34: 0 | L34: =L33+G33 -> 217
A35: =ROW()-9 -> 26 | C35: Data by counterparty | D35: AITE_SAKI_BETSU_DATA | F35: Mixed half-width characters | G35: 4000 | L35: =L34+G34 -> 230
A36: =ROW()-9 -> 27 | C36: Processing receipt number | D36: FUNC_UKETSUKE_NO | F36: Number | G36: 10 | H36: 0 | L36: =L35+G35 -> 4230
A37: =ROW()-9 -> 28 | C37: FILLER | D37: FILLER | F37: Half-width characters | G37: 2 | L37: =L36+G36 -> 4240 | M37: Line feed code (2 bytes)

Sheet  4. OUTPUT file layout (B)
A6: ■ | B6: OUTPUT file layout | E6: Record length | G6: =SUM(G10:G142) -> 1900 | H6: Character encoding | J6: SJIS
A7: [Body Record]
B8: item | H8: decimal | I8: decimal point | J8: PAC/ | K8: Shift presence/absence | L8: start
A9: No. | B9: group | C9: Item name (Japanese name) | D9: Item name (English name) | E9: Character encoding | F9: Type | G9: number of digits | H9: number of digits | I9: presence or absence | J9: UNPAC | L9: position | M9: remarks
A10: =ROW()-9 -> 1 | C10: Reserve | D10: RESERVE | F10: character | G10: 1 | L10: 1
A11: =ROW()-9 -> 2 | C11: BPID | D11: BPID | F11: character | G11: 8 | L11: =L10+G10 -> 2
A12: =ROW()-9 -> 3 | C12: Sending and receiving | D12: SND_RCV | F12: character | G12: 1 | L12: =L11+G11 -> 10
A13: =ROW()-9 -> 4 | C13: Information classification | D13: INF_KBN | F13: character | G13: 4 | L13: =L12+G12 -> 11
A14: =ROW()-9 -> 5 | C14: Company code | D14: JISHA_CD | F14: character | G14: 12 | L14: =L13+G13 -> 15
A15: =ROW()-9 -> 6 | C15: Recipient Code | D15: AITE_SAKI_CD | F15: character | G15: 12 | L15: =L14+G14 -> 27
A16: =ROW()-9 -> 7 | C16: Data Type | D16: DATA_SBT | F16: character | G16: 4 | L16: =L15+G15 -> 39
A17: =ROW()-9 -> 8 | C17: Processing classification | D17: FUNC_KBN | F17: character | G17: 1 | L17: =L16+G16 -> 43
A18: =ROW()-9 -> 9 | C18: Processing date | D18: FUNC_YMD | F18: character | G18: 6 | L18: =L17+G17 -> 44
A19: =ROW()-9 -> 10 | C19: Processing time | D19: FUNC_TM | F19: character | G19: 6 | L19: =L18+G18 -> 50
A20: =ROW()-9 -> 11 | C20: Red and Black Division | D20: AKAKURO_KBN | F20: character | G20: 1 | L20: =L19+G19 -> 56
A21: =ROW()-9 -> 12 | C21: Ordering company code | D21: HACSHA_KIGYO_CD | F21: character | G21: 6 | L21: =L20+G20 -> 57
A22: =ROW()-9 -> 13 | C22: Ordering department code | D22: HACSHA_BMN_CD | F22: character | G22: 6 | L22: =L21+G21 -> 63
... A24: =ROW()-9 -> 15 | C24: New purchaser department code | D24: NEW_HACSHA_BMN_CD | F24: character | G24: 6 | L24: =L23+G23 -> 75
A25: =ROW()-9 -> 16 | C25: Contractor company code | D25: JUC_KIGYO_CD | F25: character | G25: 6 | L25: =L22+G22 -> 69
A26: =ROW()-9 -> 17 | C26: Order recipient department code | D26: JUC_BMN_CD | F26: character | G26: 6 | L26: =L25+G25 -> 75
A27: =ROW()-9 -> 18 | C27: Claimant company code | D27: SEIKYU_KIGYO_CD | F27: character | G27: 6 | L27: =L26+G26 -> 81
A28: =ROW()-9 -> 19 | C28: Claimant department code | D28: SEIKYU_BMN_CD | F28: character | G28: 6 | L28: =L27+G27 -> 87
A29: =ROW()-9 -> 20 | C29: Payer company code | D29: PAY_KIGYO_CD | F29: character | G29: 6 | L29: =L28+G28 -> 93
A30: =ROW()-9 -> 21 | C30: Payer Department Code | D30: PAY_BMN_CD | F30: character | G30: 6 | L30: =L29+G29 -> 99
A31: =ROW()-9 -> 22 | C31: Contract number | D31: KEIYAKU_NO | F31: character | G31: 10 | L31: =L30+G30 -> 105
A32: =ROW()-9 -> 23 | C32: Implementation date | D32: JISSHI_YMD | F32: character | G32: 6 | L32: =L31+G31 -> 115
A33: =ROW()-9 -> 24 | C33: Order number | D33: CHUMON_NO | F33: character | G33: 10 | L33: =L32+G32 -> 121
A34: =ROW()-9 -> 25 | C34: Orderer and order date | D34: HACSHA_CHUMON_D | F34: character | G34: 6 | L34: =L33+G33 -> 131
A35: =ROW()-9 -> 26 | C35: Orderer and order time | D35: HACSHA_CHUMON_TM | F35: character | G35: 4 | L35: =L34+G34 -> 137
A36: =ROW()-9 -> 27 | C36: Order Class | D36: ORDER_KBN | F36: character | G36: 1 | L36: =L35+G35 -> 141
A37: =ROW()-9 -> 28 | C37: Contact necessity classification | D37: RENRAKU_YN_KBN | F37: character | G37: 1 | L37: =L36+G36 -> 142
... A71: =ROW()-9 -> 62 | C71: Quantity confirmation indicator | D71: SURYO_CONFIRM_KBN | F71: character | G71: 1 | L71: =L70+G70 -> 737
A72: =ROW()-9 -> 63 | C72: Sales price | D72: HAN_TANK | F72: Number | G72: 13 | H72: 3 | I72: Yes | J72: PAC | L72: =L71+G71 -> 738
A73: =ROW()-9 -> 64 | C73: Unit price | D73: TANK_UNIT | F73: character | G73: 3 | L73: =L72+G72 -> 751
A74: =ROW()-9 -> 65 | C74: Unit price category | D74: TANK_KBN | F74: character | G74: 1 | L74: =L73+G73 -> 754
A75: =ROW()-9 -> 66 | C75: Payment classification | D75: KOSEN_KBN | F75: character | G75: 1 | L75: =L74+G74 -> 755
A76: =ROW()-9 -> 67 | C76: Commission unit price | D76: KOSEN_TANK | F76: Number | G76: 13 | H76: 3 | I76: Yes | J76: PAC | L76: =L75+G75 -> 756
A77: =ROW()-9 -> 68 | C77: commission | D77: KOSEN | F77: Number | G77: 13 | H77: 0 | J77: PAC | L77: =L76+G76 -> 769
A78: =ROW()-9 -> 69 | C78: Secondary store payment classification | D78: NIJITEN_KOSEN_KBN | F78: character | G78: 1 | L78: =L77+G77 -> 782
A79: =ROW()-9 -> 70 | C79: Secondary store commission unit price | D79: NIJITEN_KOSEN_TANK | F79: Number | G79: 13 | H79: 3 | I79: Yes | J79: PAC | L79: =L78+G78 -> 783
...

Sheet  5. Item transfer (EDI sending DB_payment)_update
A6: ■ | B6: EDI Outbound DB_Payment Mapping Specifications
A7: EDI Outbound DB_Payment Mapping | H7: Setting value
A8: No. | B8: Item Group | C8: Item name (Japanese name) | D8: Item name (English name) | E8: Type | F8: number of digits | G8: Number of decimal places | H8: Simple transfer | I8: Editing content
A9: =ROW()-8 -> 1 | C9: Transmission Sequence No. | D9: SND_SEQ_NO | E9: Half-width alphanumeric characters | F9: 10
A10: =ROW()-8 -> 2 | C10: Data Exchange ID | D10: DATA_KOKAN_ID | E10: Half-width alphanumeric characters | F10: 6
A11: =ROW()-8 -> 3 | C11: EDI_Function Category Code | D11: EDI_KINO_CATEGORY_CD | E11: Half-width alphanumeric characters | F11: 4
A12: =ROW()-8 -> 4 | C12: Supplier Code | D12: SUP_CD | E12: Half-width numbers | F12: 10
A13: =ROW()-8 -> 5 | C13: Sales area | D13: HAN_KBN | E13: Half-width alphanumeric characters | F13: 3
A14: =ROW()-8 -> 6 | C14: Starting date | D14: KISAN_D | E14: Half-width alphanumeric characters | F14: 8
A15: =ROW()-8 -> 7 | C15: denomination | D15: KINSHU | E15: Half-width English characters | F15: 1
A16: =ROW()-8 -> 8 | C16: Head office/branch code | D16: HONSHITEN_CD | E16: Half-width numbers | F16: 1
A17: =ROW()-8 -> 9 | C17: Deadline | D17: SHIMEKIRI_YMD | E17: Date (year, month, day) | F17: 8
A18: =ROW()-8 -> 10 | C18: Maturity Date | D18: MANKI_D | E18: Half-width alphanumeric characters | F18: 8
A19: =ROW()-8 -> 11 | C19: Bank Code | D19: BANK_CD | E19: Half-width numbers | F19: 4
A20: =ROW()-8 -> 12 | C20: Branch code | D20: SHITEN_CD | E20: Half-width numbers | F20: 3
... A24: =ROW()-8 -> 16 | C24: Transfer account number | D24: FURIKOMI_KOZA_NO | E24: Half-width alphanumeric characters | F24: 7
A25: =ROW()-8 -> 17 | C25: EDI_Current payment amount | D25: EDI_KONKAI_PAY_GAKU | E25: Decimal numbers | F25: 13 | G25: 0
A26: =ROW()-8 -> 18 | C26: Payment date | D26: PAY_YMD | E26: Date (year, month, day) | F26: 8
A27: =ROW()-8 -> 19 | C27: EDI_Transmission Status Type | D27: EDI_SND_JOKYO_SBT | E27: Half-width alphanumeric characters | F27: 1 | I27: "3" (Processed)
A28: =ROW()-8 -> 20 | C28: Date and time of sending | D28: SND_DT | E28: Full-byte mixed characters | F28: 19
A29: =ROW()-8 -> 21 | C29: Transmission data deletion category | D29: SND_DATA_DEL_KBN | E29: Half-width numbers | F29: 1
A30: =ROW()-8 -> 22 | C30: Receive Sequence No. | D30: RCV_SEQ_NO | E30: Half-width alphanumeric characters | F30: 10
A31: =ROW()-8 -> 23 | C31: Processing receipt number | D31: FUNC_UKETSUKE_NO | E31: Decimal numbers | F31: 10 | G31: 0 | H31: [Processing receipt number]
A32: =ROW()-8 -> 24 | C32: Deletion category | D32: DEL_KBN | E32: Half-width numbers | F32: 1
A33: =ROW()-8 -> 25 | C33: Creation date | D33: CREATE_DT | E33: Full-byte mixed characters | F33: 19
A34: =ROW()-8 -> 26 | C34: Created by | D34: CREATE_USR | E34: Half-width alphanumeric characters | F34: 20
A35: =ROW()-8 -> 27 | C35: Creation Process | D35: CREATE_FUNC | E35: Full-byte mixed characters | F35: 64
A36: =ROW()-8 -> 28 | C36: Latest update date and time | D36: NEW_UPDATE_DT | E36: Full-byte mixed characters | F36: 19 | I36: System date and time (YYYY/MM/DD HH:MI:SS)
A37: =ROW()-8 -> 29 | C37: Latest Updated User | D37: NEW_UPDATE_USR | E37: Half-width alphanumeric characters | F37: 20 | I37: "EDI"
A38: =ROW()-8 -> 30 | C38: Latest update processing | D38: NEW_UPDATE_FUNC | E38: Full-byte mixed characters | F38: 64 | I38: "m_TUG_Payment_Payment_Details_Data_Edit_010"
A39: =ROW()-8 -> 31 | C39: Number of updates | D39: UPDATE_CNT | E39: Decimal numbers | F39: 9 | G39: 0 | I39: [Update count] +1

Sheet  6. Data layout by destination
E6: Record length | F6: =SUM(G10:G140) -> 4000
A7: ■ | B7: Data layout by destination
B8: change | C8: item | H8: decimal | I8: decimal point | J8: start
A9: No. | B9: part | C9: group | D9: Item name (Japanese name) | E9: Item name (English name) | F9: Type | G9: number of digits | H9: number of digits | I9: presence or absence | J9: position | K9: remarks
A10: =ROW()-9 -> 1 | D10: Reserve | E10: RESERVE | F10: character | G10: 1 | J10: 1
A11: =ROW()-9 -> 2 | D11: BPID | E11: BPID | F11: character | G11: 8 | J11: =J10+G10 -> 2
A12: =ROW()-9 -> 3 | D12: Sending and receiving | E12: SND_RCV | F12: character | G12: 1 | J12: =J11+G11 -> 10
A13: =ROW()-9 -> 4 | D13: Information classification | E13: INF_KBN | F13: character | G13: 4 | J13: =J12+G12 -> 11
A14: =ROW()-9 -> 5 | D14: Company code | E14: JISHA_CD | F14: character | G14: 12 | J14: =J13+G13 -> 15
A15: =ROW()-9 -> 6 | D15: Recipient Code | E15: AITE_SAKI_CD | F15: character | G15: 12 | J15: =J14+G14 -> 27
A16: =ROW()-9 -> 7 | D16: Data Type | E16: DATA_SBT | F16: character | G16: 4 | J16: =J15+G15 -> 39
A17: =ROW()-9 -> 8 | D17: Processing classification | E17: FUNC_KBN | F17: character | G17: 1 | J17: =J16+G16 -> 43
A18: =ROW()-9 -> 9 | D18: Processing date | E18: FUNC_YMD | F18: character | G18: 6 | J18: =J17+G17 -> 44
A19: =ROW()-9 -> 10 | D19: Processing time | E19: FUNC_TM | F19: character | G19: 6 | J19: =J18+G18 -> 50
A20: =ROW()-9 -> 11 | D20: Red and Black Division | E20: AKAKURO_KBN | F20: character | G20: 1 | J20: =J19+G19 -> 56
A21: =ROW()-9 -> 12 | D21: Ordering company code | E21: HACSHA_KIGYO_CD | F21: character | G21: 6 | J21: =J20+G20 -> 57
A22: =ROW()-9 -> 13 | D22: Ordering department code | E22: HACSHA_BMN_CD | F22: character | G22: 6 | J22: =J21+G21 -> 63
... A51: =ROW()-9 -> 42 | D51: Lot No. | E51: LOT_NO | F51: character | G51: 10 | J51: =J50+G50 -> 418
A52: =ROW()-9 -> 43 | D52: Customer company code | E52: JUYOKA_KIGYO_CD | F52: character | G52: 6 | J52: =J49+G49 -> 417
A53: =ROW()-9 -> 44 | D53: Customer sector code | E53: JUYOKA_BMN_CD | F53: character | G53: 6 | J53: =J50+G50 -> 418
A54: =ROW()-9 -> 45 | D54: Customer name (kana) | E54: JUYOKA_NM_KANA | F54: character | G54: 40 | J54: =J51+G51 -> 428
A55: =ROW()-9 -> 46 | D55: Consumer name (kanji) | E55: JUYOKA_NM_KANJI | F55: character | G55: 40 | J55: =J52+G52 -> 423
A56: =ROW()-9 -> 47 | D56: Customer order number | E56: JUYOKA_CHUMON_NO | F56: character | G56: 10 | J56: =J53+G53 -> 424
A57: =ROW()-9 -> 48 | D57: Secondary store company code | E57: NIJITEN_KIGYO_CD | F57: character | G57: 6 | J57: =J53+G53 -> 424
A58: =ROW()-9 -> 49 | D58: Secondary store department code | E58: NIJITEN_BMN_CD | F58: character | G58: 6 | J58: =J54+G54 -> 468
A59: =ROW()-9 -> 50 | D59: Secondary store name (kana) | E59: NIJITEN_NM_KANA | F59: character | G59: 40 | J59: =J55+G55 -> 463
A60: =ROW()-9 -> 51 | D60: Secondary store name (kanji) | E60: NIJITEN_NM_KANJI | F60: character | G60: 40 | J60: =J56+G56 -> 434
A61: =ROW()-9 -> 52 | D61: Third-tier store code | E61: SANJITEN_CD | F61: character | G61: 92 | J61: =J58+G58 -> 474
A62: =ROW()-9 -> 53 | D62: Payment terms deadline | E62: KESSAI_JOKEN_SHIMEKIRI_D | F62: character | G62: 6 | J62: =J59+G59 -> 503
A63: =ROW()-9 -> 54 | D63: Payment terms start date | E63: KESSAI_JOKEN_KISAN_D | F63: character | G63: 6 | J63: =J60+G60 -> 474
A64: =ROW()-9 -> 55 | D64: Payment terms and means | E64: KESSAI_JOKEN_SHUDAN | F64: character | G64: 1 | J64: =J61+G61 -> 566
A65: =ROW()-9 -> 56 | D65: Payment terms maturity date | E65: KESSAI_JOKEN_MANKI_D | F65: character | G65: 6 | J65: =J62+G62 -> 509
A66: =ROW()-9 -> 57 | D66: Payment terms criteria | E66: KESSAI_JOKEN_KIJUN | F66: character | G66: 1 | J66: =J63+G63 -> 480
A67: =ROW()-9 -> 58 | D67: Payment Terms | E67: KESSAI_JOKEN | F67: character | G67: 15 | J67: =J64+G64 -> 567
A68: =ROW()-9 -> 59 | D68: Quantity confirmation indicator | E68: SURYO_CONFIRM_KBN | F68: character | G68: 1 | J68: =J65+G65 -> 515
A69: =ROW()-9 -> 60 | B69: ● | D69: Sales price | E69: HAN_TANK | F69: Number | G69: 13 | H69: 3 | I69: Nothing | J69: =J66+G66 -> 481 | K69: Unpack numeric strings and use them as numbers
A70: =ROW()-9 -> 61 | D70: Unit price | E70: TANK_UNIT | F70: character | G70: 3 | J70: =J67+G67 -> 582
A71: =ROW()-9 -> 62 | D71: Unit price category | E71: TANK_KBN | F71: character | G71: 1 | J71: =J68+G68 -> 516
A72: =ROW()-9 -> 63 | D72: Payment classification | E72: KOSEN_KBN | F72: character | G72: 1 | J72: =J69+G69 -> 494
A73: =ROW()-9 -> 64 | B73: ● | D73: Commission unit price | E73: KOSEN_TANK | F73: Number | G73: 13 | H73: 3 | I73: Nothing | J73: =J70+G70 -> 585 | K73: Unpack numeric strings and use them as numbers
...

Sheet  7. Item transfer (payment details data transmission file)
A6: ■ | B6: Payment details data transmission file mapping specifications | D6: [ ]: 6. Data layout by destination | E6: △: Half-width space, □: Full-width space
A7: Payment details data sending file mapping | D7: Setting value
A8: No. | B8: Item name (Japanese name) | C8: Item name (English name) | D8: Simple transfer | E8: Editing content
A9: =ROW()-8 -> 1 | B9: Reserve | C9: RESERVE | E9: "△"
A10: =ROW()-8 -> 2 | B10: BPID | C10: BPID | E10: "JPCA0102"
A11: =ROW()-8 -> 3 | B11: Sending Type | C11: SND_RCV | E11: "S"
A12: =ROW()-8 -> 4 | B12: Information classification | C12: INF_KBN | E12: "1810"
A13: =ROW()-8 -> 5 | B13: Company code | C13: JISHA_CD | E13: "101913000110"
A14: =ROW()-8 -> 6 | B14: Recipient Code | C14: AITE_SAKI_CD | E14: "504832000001"
A15: =ROW()-8 -> 7 | B15: Data Type | C15: DATA_SBT | E15: "1810"
A16: =ROW()-8 -> 8 | B16: Processing classification | C16: FUNC_KBN | D16: [Processing category]
A17: =ROW()-8 -> 9 | B17: Processing date | C17: FUNC_YMD | E17: yymmdd (system date)
A18: =ROW()-8 -> 10 | B18: Processing time | C18: FUNC_TM | E18: HHMMSS (system time)
A19: =ROW()-8 -> 11 | B19: Red and Black Division | C19: AKAKURO_KBN | D19: [Red and black division]
A20: =ROW()-8 -> 12 | B20: Ordering company code | C20: HACSHA_KIGYO_CD | D20: [Orderer company code]
A21: =ROW()-8 -> 13 | B21: Ordering department code | C21: HACSHA_BMN_CD | D21: [Orderer department code]
A22: =ROW()-8 -> 14 | B22: New purchaser company code | C22: NEW_HACSHA_KIGYO_CD | E22: △*6
A23: =ROW()-8 -> 15 | B23: New purchaser department code | C23: NEW_HACSHA_BMN_CD | E23: △*6
A24: =ROW()-8 -> 16 | B24: Contractor company code | C24: JUC_KIGYO_CD | D24: [Contractor company code]
A25: =ROW()-8 -> 17 | B25: Order recipient department code | C25: JUC_BMN_CD | D25: [Orderer department code]
A26: =ROW()-8 -> 18 | B26: Claimant company code | C26: SEIKYU_KIGYO_CD | D26: [Claimer company code]
A27: =ROW()-8 -> 19 | B27: Claimant department code | C27: SEIKYU_BMN_CD | D27: [Claimer department code]
A28: =ROW()-8 -> 20 | B28: Payer company code | C28: PAY_KIGYO_CD | D28: [Payer company code]
A29: =ROW()-8 -> 21 | B29: Payer Department Code | C29: PAY_BMN_CD | D29: [Payer department code]
A30: =ROW()-8 -> 22 | B30: Contract number | C30: KEIYAKU_NO | D30: [Contract number]
A31: =ROW()-8 -> 23 | B31: Implementation date | C31: JISSHI_YMD | D31: [Date]
A32: =ROW()-8 -> 24 | B32: Order number | C32: CHUMON_NO | D32: [Order number]
A33: =ROW()-8 -> 25 | B33: Orderer and order date | C33: HACSHA_CHUMON_D | D33: [Order date by purchaser]
A34: =ROW()-8 -> 26 | B34: Orderer and order time | C34: HACSHA_CHUMON_TM | E34: "0000"
A35: =ROW()-8 -> 27 | B35: Order Class | C35: ORDER_KBN | E35: "△"
A36: =ROW()-8 -> 28 | B36: Contact necessity classification | C36: RENRAKU_YN_KBN | E36: "△"
A37: =ROW()-8 -> 29 | B37: Quantity specification category | C37: SURYO_SHITEI_KBN | E37: "△"
A38: =ROW()-8 -> 30 | B38: Order comment (kana) | C38: HAC_COMMENT_KANA | E38: △*44
A39: =ROW()-8 -> 31 | B39: Order comment (Kanji) | C39: HAC_COMMENT_KANJI | E39: □*22
A40: =ROW()-8 -> 32 | B40: Order number | C40: JUC_NO | D40: [Order number]
A41: =ROW()-8 -> 33 | B41: Order acceptance date | C41: JUC_CHUMON_UKETSUKE_DT | E41: "000000"
A42: =ROW()-8 -> 34 | B42: Order acceptance time | C42: JUC_CHUMON_UKETSUKE_TM | E42: "0000"
A43: =ROW()-8 -> 35 | B43: Order confirmation date | C43: JUC_CHUMON_CONFIRM_D | E43: "000000"
A44: =ROW()-8 -> 36 | B44: Installment payment categories | C44: BUNNO_KBN | D44: [Installment payment category]
A45: =ROW()-8 -> 37 | B45: Order processing category | C45: JUC_FUNC_KBN | E45: "△"
...

Sheet  8. [Reference] Basic design
A1: Inabata & Co., Ltd. | G1: Basic design | R1: System Name | AW1: Subsystem name | BD1: Feature ID
R3: Techno UMG (payment details data) | AW3: EDI | BD3: -
B7: 1. | C7: Business flow explanation
C8: ① Send the payment details data created based on the "shipping invoice data" that is the subject of EDI payment.
B10: 2. | C10: specification
C11: ① Extraction of data to be sent
D12: ・DB (EDI Send DB_Payment) extraction conditions
D13: Data Exchange ID="000086"
D14: and EDI_Function Category Code="A140"
D15: And EDI_SendStatusType="0" (Unprocessed)
D17: ・DB (EDI receiving DB_Supplier) extraction conditions
D18: Data Exchange ID="000086"
D19: and EDI_Function Category Code="A100"
D21: ・DB (EDI sending DB_Payment) and DB (EDI receiving DB_Supplier) are linked by the receiving sequence number.
C23: ②If there is no target data
D24: - After outputting the message "0 items", the process will terminate abnormally.
D25: Unless a transaction is suspended, the number of payments will never be zero, so it is an irregular situation for the number of items to be sent to be zero.
D26: To detect that there are 0 targets, the process will be terminated abnormally, and once it has been confirmed that there are no operational issues, the job net will be recovered (perform the "Confirm" operation).
B28: 3. | C28: Sending item design
C30: ・Created based on the data in "EDI Send DB_Payment"
C31: For payment details data file layout and editing specifications, refer to the "Transmission Item Table (Payment Details)" sheet.

Sheet  9. [Reference] Sending Item List (Payment Details)
H6: [ ]: EDI receiving DB_Supplier " ": EDI sending DB_Payment
H7: △: Half-width space, □: Full-width space *n (n: number of repetitions)
B8: No. | C8: Item name | D8: Item character type | E8: Number of digits (bytes) | F8: Decimal places | G8: Required Optional Not used | H8: edit | I8: remarks
B9: 1 | C9: Reserve | D9: character | E9: 1 | G9: - | H9: △*1 | I9: In the NTS conversion process, this item is deleted.
B10: =B9+1 -> 2 | C10: BPID | D10: character | E10: 8 | G10: - | H10: "JPCA0102" | I10: In the NTS conversion process, this item is deleted.
B11: =B10+1 -> 3 | C11: Sending and receiving | D11: character | E11: 1 | G11: - | H11: "S" | I11: In the NTS conversion process, this item is deleted.
B12: =B11+1 -> 4 | C12: Information classification | D12: character | E12: 4 | G12: - | H12: "1810" [Payment details] | I12: In the NTS conversion process, this item is deleted.
B13: =B12+1 -> 5 | C13: Company code | D13: character | E13: 12 | G13: - | H13: "101913000110" | I13: In the NTS conversion process, this item is deleted.
B14: =B13+1 -> 6 | C14: Recipient Code | D14: character | E14: 12 | G14: - | H14: "504832000001" | I14: In the NTS conversion process, this item is deleted.
B15: =B14+1 -> 7 | C15: Data Type | D15: character | E15: 4 | G15: Required | H15: "1810" [Payment details] | L15: mixed string
B16: =B15+1 -> 8 | C16: Processing classification | D16: character | E16: 1 | G16: Required | H16: byte from 43rd byte of [Destination Data] | I16: Shipping billing turnaround | L16: mixed string
B17: =B16+1 -> 9 | C17: Processing date | D17: character | E17: 6 | G17: Required | H17: Job execution date: "YYMMDD" | L17: mixed string
B18: =B17+1 -> 10 | C18: Processing time | D18: character | E18: 6 | G18: Required | H18: Job execution time: "HHMMSS" | L18: mixed string
B19: =B18+1 -> 11 | C19: Red and Black Division | D19: character | E19: 1 | G19: Required | H19: 1 byte from the 56th byte of [Destination Data] | I19: Shipping billing turnaround | L19: mixed string
B20: =B19+1 -> 12 | C20: Ordering company code | D20: character | E20: 6 | G20: Required | H20: 6 bytes from byte 57 of [Destination Data] | I20: Shipping billing turnaround | L20: mixed string
B21: =B20+1 -> 13 | C21: Ordering department code | D21: character | E21: 6 | G21: Required | H21: 6 bytes from the 63rd byte of [Destination Data] | I21: Shipping billing turnaround | L21: mixed string
B22: =B21+1 -> 14 | C22: New purchaser company code | D22: character | E22: 6 | G22: - | H22: △*6 | I22: In the NTS conversion process, this item is deleted.
B23: =B22+1 -> 15 | C23: New purchaser department code | D23: character | E23: 6 | G23: - | H23: △*6 | I23: In the NTS conversion process, this item is deleted.
B24: =B23+1 -> 16 | C24: Contractor company code | D24: character | E24: 6 | G24: Required | H24: 6 bytes from byte 81 of [Destination Data] | I24: Shipping billing turnaround | L24: mixed string
B25: =B24+1 -> 17 | C25: Order recipient department code | D25: character | E25: 6 | G25: Required | H25: 6 bytes from byte 87 of [Destination Data] | I25: Shipping billing turnaround | L25: mixed string
B26: =B25+1 -> 18 | C26: Claimant company code | D26: character | E26: 6 | G26: Required | H26: bytes from byte 93 of [Destination Data] | I26: Shipping billing turnaround | L26: mixed string
B27: =B26+1 -> 19 | C27: Claimant department code | D27: character | E27: 6 | G27: Required | H27: 6 bytes from the 99th byte of [Destination Data] | I27: Shipping billing turnaround | L27: mixed string
B28: =B27+1 -> 20 | C28: Payer company code | D28: character | E28: 6 | G28: Required | H28: 6 bytes from byte 105 of [Destination Data] | I28: Shipping billing turnaround | L28: mixed string
B29: =B28+1 -> 21 | C29: Payer Department Code | D29: character | E29: 6 | G29: Required | H29: 6 bytes from byte 111 of [Destination Data] | I29: Shipping billing turnaround | L29: mixed string
B30: =B29+1 -> 22 | C30: Contract number | D30: character | E30: 10 | G30: Required | H30: 10 bytes from byte 117 of [Destination Data] | I30: Shipping billing turnaround | L30: mixed string
B31: =B30+1 -> 23 | C31: Implementation date | D31: character | E31: 6 | G31: Unused | H31: "000000" | L31: mixed string
B32: =B31+1 -> 24 | C32: Order number | D32: character | E32: 10 | G32: Required | H32: 10 bytes from byte 133 of [Destination Data] | I32: Shipping billing turnaround | L32: mixed string
B33: =B32+1 -> 25 | C33: Orderer and order date | D33: character | E33: 6 | G33: Required | H33: 6 bytes from byte 143 of [Destination Data] | I33: Shipping billing turnaround | L33: mixed string
B34: =B33+1 -> 26 | C34: Orderer and order time | D34: character | E34: 4 | G34: Unused | H34: "0000" | L34: mixed string
B35: =B34+1 -> 27 | C35: Order Class | D35: character | E35: 1 | G35: Unused | H35: △*1 | L35: mixed string
B36: =B35+1 -> 28 | C36: Contact necessity classification | D36: character | E36: 1 | G36: Unused | H36: △*1 | L36: mixed string
B37: =B36+1 -> 29 | C37: Quantity specification category | D37: character | E37: 1 | G37: Unused | H37: △*1 | L37: mixed string
B38: =B37+1 -> 30 | C38: Order comment (kana) | D38: character | E38: 44 | G38: Unused | H38: △*44 | L38: mixed string
B39: =B38+1 -> 31 | C39: Order comment (Kanji) | D39: character | E39: 44 | G39: Unused | H39: □*22 | L39: Kanji
B40: =B39+1 -> 32 | C40: Order number | D40: character | E40: 10 | G40: Required | H40: 10 bytes from byte 244 of [Destination Data] | I40: Shipping billing turnaround | L40: mixed string
B41: =B40+1 -> 33 | C41: Order acceptance date | D41: character | E41: 6 | G41: Unused | H41: "000000" | L41: mixed string
B42: =B41+1 -> 34 | C42: Order acceptance time | D42: character | E42: 4 | G42: Unused | H42: "0000" | L42: mixed string
B43: =B42+1 -> 35 | C43: Order confirmation date | D43: character | E43: 6 | G43: Unused | H43: "000000" | L43: mixed string
B44: =B43+1 -> 36 | C44: Installment payment categories | D44: character | E44: 1 | G44: Required | H44: 1 byte from byte 270 of [Destination Data] | I44: Shipping billing turnaround | L44: mixed string
B45: =B44+1 -> 37 | C45: Order processing category | D45: character | E45: 1 | G45: Unused | H45: △*1 | L45: mixed string
...
