Workbook
Name _1枚目: #REF!
Name _1枚目: #REF!
Name _2枚目: #REF!
Name _2枚目: #REF!
Name _3枚目: #REF!
Name _3枚目: #REF!
Name _4枚目: #REF!
Name a: #REF!
Name a: #REF!
Name AA: #REF!
Name AA: #REF!
Name b: #REF!
Name b: #REF!
Name B_下: #REF!
Name B_上: #REF!
Name CSV項目編集仕様: #REF!
Name dd: #REF!
Name DS_下: #REF!
Name DS_上: #REF!
Name ＤＳ担当: #REF!
Name GUI名称: #REF!
Name ＩＤ: #REF!
Name IO: #REF!
Name IT項目: #REF!
Name kkk: #REF!
Name NULL: #REF!
Name ON: #REF!
Name PCL_下: #REF!
Name PCL_上: #REF!
Name ＰＧ担当: #REF!
Name PT項目: #REF!
Name PT項目: #REF!
Name RI: #REF!
Name RI: #REF!
Name riyu: #REF!
Name riyu: #REF!
Name RYZ: #REF!
Name STEP_下: #REF!
Name STEP_上: #REF!
Name UD: #REF!
Name x: '３．INPUTファイルレイアウト(B)（連携ファイル）'!x
Name x: [0]!x
Name カーソルキー移動↑↓←: #REF!
Name カーソルキー移動↑↓←: #REF!
Name カテゴリ一覧: #REF!
Name カテゴリ一覧: #REF!
Name クラス名: #REF!
Name クラス名: #REF!
Name サブシステム名: #REF!
Name システム名: #REF!
Name セパレータ: #REF!
Name タイトル: #REF!
Name チェック: #REF!
Name チェック実行アプリ: #REF!
Name ﾃｰﾌﾞﾙID群: #REF!
Name ファイル名: #REF!
Name ファンクションキー割当: #REF!
Name ブロック: #REF!
Name ブロックＩＤ: #REF!
Name レベル: #REF!

Sheet 連携ファイル分割
A1: 連携ファイル分割
B3: No. | C3: テストNo | D3: inputファイルデータ
C4: 【テスト結果】 | D4: DNKA130S02001を以下に貼り付ける
B5: =B4+1 -> 1 | C5: No34,35,39 | D5: S5017087850* SA0544102100SA05441021#JPCA0102R1710101913000010114876000001171011706300901282 3040TSM2 A0001916 A1713201T000000005001531460000000000 ４ｔ車迄可パレット不／注ＮＯ．０５００１５３01092051481706201102000010 PS1 AT01G200CFEC Ｇ２００Ｃ ５００ｋｇフレコン 7621H6 A1713201 ニッポー 本社 17063017073131708311 10000000178000KG 200000000040000000000000000 00000000000000000000000000A1713201 ニッポー 本社 氷野２－３－７ 27 5740062072-870-8866072-870-7610170630 170630 新ＬＯＴ試験成績書添付／ＡＭ着希望 0000000000000 0910564156000010 0000000 00000030000000000000006000KG 00000030000000000000000000BAG 0000000500000000000053400000000005126400000000041011000000055365111 11 206291706290811754126900001 MC00 大東市 2017020001323100110 1 JPY 0910564156000010 631242
B6: =B5+1 -> 2 | C6: No34,35,39 | D6: S5017087841* SA0544102200SA05441022#JPCA0102R1710101913000010114876000001171011706300901282 3040TSM2 A0001916 A1713201T000000005001531480000000000 ４ｔ車迄可パレット不／注ＮＯ．０５００１５３01092051791706201105000010 PS2 AT03H350XFEC Ｈ３５０ ５００ｋｇフレコン 7614R3 A1713201 ニッポー 本社 17063017073131708311 10000000183000KG 200000000040000000000000000 00000000000000000000000000A1713201 ニッポー 本社 氷野２－３－７ 27 5740062072-870-8866072-870-7610170630 170630 新ＬＯＴ試験成績書添付／ＡＭ着希望 0000000000000 0910564157000010 0000000 00000010000000000000002000KG 00000010000000000000000000BAG 0000000500000000000018300000000001756800000000014054000000018973411 11 206291706290811754127900001 MC00 大東市 2017020001323200110 1 JPY 0910564157000010 631242
B7: =B6+1 -> 3 | D7: S5017077652* SA0544102300SA05441023#JPCA0102R1710101913000010114876000001171011706300901302 3040TSM2 A0001917 A2129803T00000002906 0000000000 近藤様宛 ロット：７６２１Ｈ６ ※７３０３Ｆ01092183291706261505000010 PS1 AT01G200C1RC Ｇ２００Ｃ ２５ｋｇ袋 7621H6 A2129803 三笠産業 本社 17063017073131708311 10000000306000KG 200000000040000000000000000 00000000000000000000000000A2129803 三笠産業 本社 寺戸５３ 29 63508170745-56-5581 170630 170630 0000000000000 0910564190000010 0000000 00000000250000000000001000KG 00000000250000000000000000BAG 0000000025000000000000765000000000073440000000000588000000000793211 11 206291706290811754128900001 MC00 北葛城郡広陵町 2017020001324200110 1 JPY 0910564190000010 631242
B8: =B7+1 -> 4 | D8: S5017087903* SA0544102400SA05441024#JPCA0102R1710101913000010114876000001171011706300901272 3040TSM2 A0001916 A1713201T000000005001533630000000000 ※空パレ空フレ引取願います！ 01092206101706271130000010 PS1 AT01MW1CXFFA ＭＷ１Ｃ １ｔフレコン 70619ECB A1713201 ニッポー 本社 17063017073131708311 10000000191000KG 200000000040000000000000000 000000000000000000000000000000136615 ニッポー 関東工場 新井新田５０番地 11 34911460480-72-1113 170630 170630 新ＬＯＴ試験成績書添付／ＡＭ着希望 0000000000000 0910564154000010 0000000 00000080000000000000008000KG 00000080000000000000000000BAG 0000001000000000000152800000000014668800000000117350000000158423011 11 206291706290811750166900001 MA00 加須市 2017020001322900110 1 JPY 0910564154000010 631242
B9: =B8+1 -> 5 | D9: S5017087994* SA0544443700SA05444437#JPCA0102R1710101913000010114876000001171011707030901272 3040TSM1 A0001924 A1156800T0000000* 0000000000 ＡＭ着希望 01092108551706221025000010 PS1 AT01MW1DX1RA ＭＷ１Ｄ ２５ｋｇ袋 70417ECB A1156800 関プラスチック工業 A0801700 沢井商会 17063017073131710101 10000000222000KG 200000000060000000000000000 00000000000000000000000000A1156800 関プラスチック工業 明生町２－７－１０ 21 501390405752-2-4352 170629 170629 0000000000000 0910567897000010 0000000 00000005000000000000020000KG 00000005000000000000000000BAG 0000000025000000000011100000000001043400000000008347000000011268711 11 206291706290811755416000010 S521 関市 2017020001334300110 1 JPY 0910567897000010 631242
B10: =B9+1 -> 6 | D10: S5017087985* SA0544443800SA05444438#JPCA0102R1710101913000010114876000001171011707030901282 3040TSM2 A0001916 A1713201T000000005001533280000000000 パレット不要（フレコン時）４Ｔ車指定 01092175211706261310000010 PS1 AT01G200CFWC Ｇ２００Ｃ １ｔフレコン＿ＦＷ 7621H6 A1713201 ニッポー 本社 17063017073131708311 10000000178000KG 200000000040000000000000000 000000000000000000000000000000092395 テラヨシ 寺戸３１２－１ 29 635081707455-6-4730 170703 170703 ＡＭ着希望 0000000000000 0910567953000010 0000000 00000020000000000000002000KG 00000020000000000000000000BAG 0000001000000000000035600000000003417600000000027341000000036910111 11 206301706300811757227900001 MC00 北葛城郡広陵町 2017020001337900110 1 JPY 0910567953000010 631242
B11: =B10+1 -> 7 | D11: S5017087976* SA0544443900SA05444439#JPCA0102R1710101913000010114876000001171011707030901282 3040TSM2 A0001916 A1713201T000000005001533280000000000 パレット不要（フレコン時）４Ｔ車指定 01092175271706261311000010 PS2 AT03H350XFWC Ｈ３５０ １ｔフレコン＿ＦＷ 7614R3 A1713201 ニッポー 本社 17063017073131708311 10000000183000KG 200000000040000000000000000 000000000000000000000000000000092395 テラヨシ 寺戸３１２－１ 29 635081707455-6-4730 170703 170703 ＡＭ着希望 0000000000000 0910567954000010 0000000 00000010000000000000001000KG 00000010000000000000000000BAG 0000001000000000000018300000000001756800000000014054000000018973411 11 206301706300811757229900001 MC00 北葛城郡広陵町 2017020001338000110 1 JPY 0910567954000010 631242
B12: =B11+1 -> 8
B13: =B12+1 -> 9
B14: =B13+1 -> 10
B15: =B14+1 -> 11
B16: =B15+1 -> 12
B17: =B16+1 -> 13
B18: =B17+1 -> 14
B19: =B18+1 -> 15
B20: =B19+1 -> 16
B21: =B20+1 -> 17
B22: =B21+1 -> 18
B23: =B22+1 -> 19
... B46: =B45+1 -> 42

Sheet ３．INPUTファイルレイアウト(B)（連携ファイル）
A6: ■ | B6: INPUTファイルレイアウト | E6: レコード長 | G6: 4143 | H6: 文字コード | J6: SJIS
A7: 【ボディレコード】
B8: 項目 | H8: 小数 | I8: 小数点 | J8: PAC/ | K8: Ｓｈｉｆｔ 有無 | L8: 開始
A9: № | B9: グループ | C9: 項 目 名（和名） | D9: 項目名（英名） | E9: 文字コード | F9: 型 | G9: 桁数 | H9: 桁数 | I9: 有無 | J9: UNPAC | L9: 位置 | M9: 備 考
A10: =ROW()-9 -> 1 | C10: 送信シーケンスNO | D10: SND_SEQ_NO | F10: 文字 | G10: 10 | L10: 1
A11: =ROW()-9 -> 2 | C11: 計上状況種別 | D11: KEIJO_JOKYO_SBT | F11: 数値 | G11: 1 | L11: 11
A12: =ROW()-9 -> 3 | C12: エラーメッセージ(否認理由) | D12: ERR_MSG_HININ_RIYU | F12: 文字 | G12: 100 | L12: 12
A13: =ROW()-9 -> 4 | C13: 受信シーケンスNO_1 | D13: RCV_SEQ_NO_1 | F13: 文字 | G13: 10 | L13: 112
A14: =ROW()-9 -> 5 | C14: 送信データ削除区分 | D14: SND_DATA_DEL_KBN | F14: 数値 | G14: 1 | L14: 122
A15: =ROW()-9 -> 6 | C15: 削除区分 | D15: DEL_KBN | F15: 数値 | G15: 1 | L15: 123
A16: =ROW()-9 -> 7 | C16: 受信シーケンスNO_2 | D16: RCV_SEQ_NO_2 | F16: 文字 | G16: 10 | L16: 124
A17: =ROW()-9 -> 8 | C17: リザーブ | D17: RESERVE | F17: 文字 | G17: 1 | L17: 134
A18: =ROW()-9 -> 9 | C18: BPID | D18: BPID | F18: 文字 | G18: 8 | L18: 135
A19: =ROW()-9 -> 10 | C19: 送受信 | D19: SND_RCV | F19: 文字 | G19: 1 | L19: 143
A20: =ROW()-9 -> 11 | C20: 情報区分 | D20: INF_KBN | F20: 文字 | G20: 4 | L20: 144
A21: =ROW()-9 -> 12 | C21: 自社コード | D21: JISHA_CD | F21: 文字 | G21: 12 | L21: 148
... A78: =ROW()-9 -> 69 | C78: 数量確定区分 | D78: SURYO_CONFIRM_KBN | F78: 文字 | G78: 1 | L78: 882
A79: =ROW()-9 -> 70 | B79: ● | C79: 販売単価 | D79: HAN_TANK | F79: 数値 | G79: 13 | H79: 3 | I79: 無 | L79: 883 | M79: アンパック数値文字列を数値に変換し使用
A80: =ROW()-9 -> 71 | C80: 単価単位 | D80: TANK_UNIT | F80: 文字 | G80: 3 | L80: 896
A81: =ROW()-9 -> 72 | C81: 単価区分 | D81: TANK_KBN | F81: 文字 | G81: 1 | L81: 899
A82: =ROW()-9 -> 73 | C82: 口銭区分 | D82: KOSEN_KBN | F82: 文字 | G82: 1 | L82: 900
A83: =ROW()-9 -> 74 | B83: ● | C83: 口銭単価 | D83: KOSEN_TANK | F83: 数値 | G83: 13 | H83: 3 | I83: 無 | L83: 901 | M83: アンパック数値文字列を数値に変換し使用
A84: =ROW()-9 -> 75 | B84: ● | C84: 口銭金額 | D84: KOSEN_GAKU | F84: 数値 | G84: 13 | H84: 0 | L84: 914 | M84: アンパック数値文字列を数値に変換し使用
A85: =ROW()-9 -> 76 | C85: 2次店口銭区分 | D85: NIJITEN_KOSEN_KBN | F85: 文字 | G85: 1 | L85: 927
A86: =ROW()-9 -> 77 | B86: ● | C86: 2次店口銭単価 | D86: NIJITEN_KOSEN_TANK | F86: 数値 | G86: 13 | H86: 3 | I86: 無 | L86: 928 | M86: アンパック数値文字列を数値に変換し使用
A87: =ROW()-9 -> 78 | B87: ● | C87: 2次店口銭金額 | D87: NIJITEN_KOSEN_GAKU | F87: 数値 | G87: 13 | H87: 0 | L87: 941 | M87: アンパック数値文字列を数値に変換し使用
A88: =ROW()-9 -> 79 | C88: 納入先企業コード | D88: NNY_KIGYO_CD | F88: 文字 | G88: 6 | L88: 954
A89: =ROW()-9 -> 80 | C89: 納入先部門コード | D89: NNY_BMN_CD | F89: 文字 | G89: 6 | L89: 960
A90: =ROW()-9 -> 81 | C90: 納入先名称（カナ） | D90: NNY_NM_KANA | F90: 文字 | G90: 40 | L90: 966
A91: =ROW()-9 -> 82 | C91: 納入先名称（漢字） | D91: NNY_NM_KANJI | F91: 文字 | G91: 40 | L91: 1006
A92: =ROW()-9 -> 83 | C92: 受渡条件 | D92: UKEWATASHI_JOKEN | F92: 文字 | G92: 2 | L92: 1046
A93: =ROW()-9 -> 84 | C93: 受渡場所住所（カナ） | D93: UKEWATASHI_BASHO_ADDRK | F93: 文字 | G93: 74 | L93: 1048
A94: =ROW()-9 -> 85 | C94: 受渡場所住所（漢字） | D94: UKEWATASHI_BASHO_ADDR | F94: 文字 | G94: 74 | L94: 1122
A95: =ROW()-9 -> 86 | C95: 地区コード | D95: CHIKU_CD | F95: 文字 | G95: 11 | L95: 1196
A96: =ROW()-9 -> 87 | C96: 郵便番号 | D96: ZIP | F96: 文字 | G96: 7 | L96: 1207
A97: =ROW()-9 -> 88 | C97: 電話番号 | D97: TEL | F97: 文字 | G97: 12 | L97: 1214
A98: =ROW()-9 -> 89 | C98: FAX番号 | D98: FAX | F98: 文字 | G98: 12 | L98: 1226
A99: =ROW()-9 -> 90 | C99: 希望納入日 | D99: KIBO_NONYU_D | F99: 文字 | G99: 6 | L99: 1238
... A104: =ROW()-9 -> 95 | C104: 納入要件（漢字） | D104: NONYU_YOKEN_KANJI | F104: 文字 | G104: 44 | L104: 1308
A105: =ROW()-9 -> 96 | B105: ● | C105: 支払金額 | D105: PAY_GAKU | F105: 数値 | G105: 13 | H105: 0 | L105: 1352
...

Sheet 連携ファイル_項目分割
A1: 項目分割
C3: 開始位置 | D3: 1 | E3: 11 | F3: 12 | G3: 112 | H3: 122 | I3: 123 | J3: 124 | K3: 134 | L3: 135 | M3: 143 | N3: 144 | O3: 148 | P3: 160 | Q3: 172 | R3: 176 | S3: 177 | T3: 183 | U3: 189 | V3: 190 | W3: 196 | X3: 202 | Y3: 208 | Z3: 214 | AA3: 220 | AB3: 226 | AC3: 232 | AD3: 238 | AE3: 244 | AF3: 250 | AG3: 260 | AH3: 266 | AI3: 276 | AJ3: 282 | AK3: 286 | AL3: 287 | AM3: 288 | AN3: 289 | AO3: 333 | AP3: 377 | AQ3: 387 | AR3: 393 | AS3: 397 | AT3: 403 | AU3: 404 | AV3: 405 | AW3: 410 | AX3: 480 | AY3: 550 | AZ3: 551 | BA3: 561 | BB3: 573 | BC3: 613 | BD3: 653 | BE3: 663 | BF3: 675 | BG3: 715 | BH3: 755 | BI3: 767 | BJ3: 807 | BK3: 847 | BL3: 853 | BM3: 859 | BN3: 860 | BO3: 866 | BP3: 867 | BQ3: 882 | BR3: 883 | BS3: 896 | BT3: 899 | BU3: 900 | BV3: 901 | BW3: 914 | BX3: 927 | BY3: 928 | BZ3: 941 | CA3: 954 | CB3: 966 | CC3: 1006 | CD3: 1046 | CE3: 1048 | CF3: 1122 | CG3: 1196 | CH3: 1207 | CI3: 1214 | CJ3: 1226 | CK3: 1238 | CL3: 1244 | CM3: 1248 | CN3: 1258 | CO3: 1264 | CP3: 1308 | CQ3: 1352 | CR3: 1365 | CS3: 1377 | CT3: 1389 | CU3: 1396 | CV3: 1426 | CW3: 1433 | CX3: 1463 | CY3: 1470 | CZ3: 1480 | DA3: 1493 | DB3: 1506 | DC3: 1509 | DD3: 1522 | DE3: 1535 | DF3: 1545 | DG3: 1558 | DH3: 1571 | DI3: 1584 | DJ3: 1597 | DK3: 1610 | DL3: 1611 | DM3: 1612 | DN3: 1613 | DO3: 1614 | DP3: 1616 | DQ3: 1617 | DR3: 1621 | DS3: 1627 | DT3: 1652 | DU3: 1662 | DV3: 1667 | DW3: 1711 | DX3: 1755 | DY3: 1757 | DZ3: 1767 | EA3: 1787 | EB3: 1807 | EC3: 1808 | ED3: 1818 | EE3: 1862 | EF3: 1906 | EG3: 1907 | EH3: 1937 | EI3: 1967 | EJ3: 2034 | EK3: 4134 | EL3: 2034 | EM3: 4134
C4: 桁数 | D4: 10 | E4: 1 | F4: 100 | G4: 10 | H4: 1 | I4: 1 | J4: 10 | K4: 1 | L4: 8 | M4: 1 | N4: 4 | O4: 12 | P4: 12 | Q4: 4 | R4: 1 | S4: 6 | T4: 6 | U4: 1 | V4: 6 | W4: 6 | X4: 6 | Y4: 6 | Z4: 6 | AA4: 6 | AB4: 6 | AC4: 6 | AD4: 6 | AE4: 6 | AF4: 10 | AG4: 6 | AH4: 10 | AI4: 6 | AJ4: 4 | AK4: 1 | AL4: 1 | AM4: 1 | AN4: 44 | AO4: 44 | AP4: 10 | AQ4: 6 | AR4: 4 | AS4: 6 | AT4: 1 | AU4: 1 | AV4: 5 | AW4: 70 | AX4: 70 | AY4: 1 | AZ4: 10 | BA4: 12 | BB4: 40 | BC4: 40 | BD4: 10 | BE4: 12 | BF4: 40 | BG4: 40 | BH4: 12 | BI4: 40 | BJ4: 40 | BK4: 6 | BL4: 6 | BM4: 1 | BN4: 6 | BO4: 1 | BP4: 15 | BQ4: 1 | BR4: 13 | BS4: 3 | BT4: 1 | BU4: 1 | BV4: 13 | BW4: 13 | BX4: 1 | BY4: 13 | BZ4: 13 | CA4: 12 | CB4: 40 | CC4: 40 | CD4: 2 | CE4: 74 | CF4: 74 | CG4: 11 | CH4: 7 | CI4: 12 | CJ4: 12 | CK4: 6 | CL4: 4 | CM4: 10 | CN4: 6 | CO4: 44 | CP4: 44 | CQ4: 13 | CR4: 12 | CS4: 12 | CT4: 7 | CU4: 30 | CV4: 7 | CW4: 30 | CX4: 7 | CY4: 10 | CZ4: 13 | DA4: 13 | DB4: 3 | DC4: 13 | DD4: 13 | DE4: 10 | DF4: 13 | DG4: 13 | DH4: 13 | DI4: 13 | DJ4: 13 | DK4: 1 | DL4: 1 | DM4: 1 | DN4: 1 | DO4: 2 | DP4: 1 | DQ4: 4 | DR4: 6 | DS4: 25 | DT4: 10 | DU4: 5 | DV4: 44 | DW4: 44 | DX4: 2 | DY4: 10 | DZ4: 20 | EA4: 20 | EB4: 1 | EC4: 10 | ED4: 44 | EE4: 44 | EF4: 1 | EG4: 30 | EH4: 30 | EI4: 67 | EJ4: 2100 | EK4: 10 | EL4: 2100 | EM4: 10
B5: No. | C5: テストNo | D5: 送信シーケンスNO | E5: 計上状況種別 | F5: エラーメッセージ(否認理由) | G5: 受信シーケンスNO_1 | H5: 送信データ削除区分 | I5: 削除区分 | J5: 受信シーケンスNO_2 | K5: リザーブ | L5: BPID | M5: 送受信 | N5: 情報区分 | O5: 自社コード | P5: 相手先企業コード | Q5: 相手先部門コード | R5: データ種別 | S5: 処理区分 | T5: 処理年月日 | U5: 処理時刻 | V5: 赤黒区分 | W5: 発注者企業コード | X5: 発注者部門コード | Y5: 新発注者企業コード | Z5: 新発注者部門コード | AA5: 受注者企業コード | AB5: 受注者部門コード | AC5: 請求者企業コード | AD5: 請求者部門コード | AE5: 支払者企業コード | AF5: 支払者部門コード | AG5: 契約番号 | AH5: 実施日 | AI5: 注文番号 | AJ5: 発注者注文日 | AK5: 発注者注文時刻 | AL5: オーダー区分 | AM5: 連絡要否区分 | AN5: 数量指定区分 | AO5: 発注者コメント（カナ） | AP5: 発注者コメント（漢字） | AQ5: 受注番号 | AR5: 受注者注文受付日付 | AS5: 受注者注文受付時刻 | AT5: 受注者注文確定日 | AU5: 分納区分 | AV5: 受注者処理区分 | AW5: 品名グループ | AX5: 品名（カナ） | AY5: 品名（漢字） | AZ5: ロット番号指定区分 | BA5: ロット番号 | BB5: 需要家企業コード | BC5: 需要家部門コード | BD5: 需要家名称（カナ） | BE5: 需要家名称（漢字） | BF5: 需要家注文番号 | BG5: 2次店コード | BH5: 2次店名称（カナ） | BI5: 2次店名称（漢字） | BJ5: 3次店企業コード | BK5: 3次店部門コード | BL5: 3次店名称（カナ） | BM5: 3次店名称（漢字） | BN5: 決済条件締切日 | BO5: 決済条件起算日 | BP5: 決済条件手段 | BQ5: 決済条件満期日 | BR5: 決済条件基準 | BS5: 決済条件 | BT5: 数量確定区分 | BU5: 販売単価 | BV5: 単価単位 | BW5: 単価区分 | BX5: 口銭区分 | BY5: 口銭単価 | BZ5: 口銭金額 | CA5: 2次店口銭区分 | CB5: 2次店口銭単価 | CC5: 2次店口銭金額 | CD5: 納入先企業コード | CE5: 納入先部門コード | CF5: 納入先名称（カナ） | CG5: 納入先名称（漢字） | CH5: 受渡条件 | CI5: 受渡場所住所（カナ） | CJ5: 受渡場所住所（漢字） | CK5: 地区コード | CL5: 郵便番号 | CM5: 電話番号 | CN5: FAX番号 | CO5: 希望納入日 | CP5: 希望納入時刻 | CQ5: 希望納入コメント | CR5: 納入年月日 | CS5: 納入要件（カナ） | CT5: 納入要件（漢字） | CU5: 支払金額 | CV5: 支払整理番号 | CW5: 銀行情報 | CX5: 注文数量 | CY5: 注文･販売個数 | CZ5: 注文数量単位 | DA5: 販売個数 | DB5: 金額算出数量 | DC5: 荷姿コード | DD5: 荷姿名 | DE5: 容量 | DF5: 販売金額 | DG5: 請求金額 | DH5: 消費税額 | DI5: 税込請求額 | DJ5: 単価･金額区分 | DK5: 取引区分 | DL5: 遡及区分 | DM5: 出荷請求区分 | DN5: 課税区分 | DO5: バックオーダー区分 | DP5: 計上年月日 | DQ5: 適用税率 | DR5: 請求者登録番号 | DS5: 返品資産の基譲渡日 | DT5: 出荷請求年月日(予定) | DU5: 出荷報告番号 | DV5: 出荷請求番号 | DW5: 出荷場所 | DX5: 出荷指図コメント（カナ） | DY5: 出荷指図コメント（漢字） | DZ5: 輸送手段 | EA5: 輸送車種 | EB5: 発注者情報 | EC5: 受注者情報 | ED5: 国内輸出区分 | EE5: エラー理由 | EF5: エラーコメント（カナ） | EG5: エラーコメント（漢字） | EH5: 請求確認区分 | EI5: 予備欄 | EJ5: 予備欄（漢字） | EK5: 余白 | EL5: カラム1 | EM5: 処理受付番号
D6: SND_SEQ_NO | E6: KEIJO_JOKYO_SBT | F6: ERR_MSG_HININ_RIYU | G6: RCV_SEQ_NO_1 | H6: SND_DATA_DEL_KBN | I6: DEL_KBN | J6: RCV_SEQ_NO_2 | K6: RESERVE | L6: BPID | M6: SND_RCV | N6: INF_KBN | O6: JISHA_CD | P6: AITE_SAKI_KIGYO_CD | Q6: AITE_SAKI_BMN_CD | R6: DATA_SBT | S6: FUNC_KBN | T6: FUNC_YMD | U6: FUNC_TM | V6: AKAKURO_KBN | W6: HACSHA_KIGYO_CD | X6: HACSHA_BMN_CD | Y6: NEW_HACSHA_KIGYO_CD | Z6: NEW_HACSHA_BMN_CD | AA6: JUC_KIGYO_CD | AB6: JUC_BMN_CD | AC6: SEIKYU_KIGYO_CD | AD6: SEIKYU_BMN_CD | AE6: PAY_KIGYO_CD | AF6: PAY_BMN_CD | AG6: KEIYAKU_NO | AH6: JISSHI_D | AI6: CHUMON_NO | AJ6: HACSHA_CHUMON_D | AK6: HACSHA_CHUMON_TM | AL6: ORDER_KBN | AM6: RENRAKU_YN_KBN | AN6: SURYO_SHITEI_KBN | AO6: HACSHA_COMMENT_KANA | AP6: HACSHA_COMMENT_KANJI | AQ6: JUC_NO | AR6: JUC_CHUMON_UKETSUKE_DT | AS6: JUC_CHUMON_UKETSUKE_TM | AT6: JUC_CHUMON_CONFIRM_D | AU6: BUNNO_KBN | AV6: JUC_FUNC_KBN | AW6: HINMEI_GROUP | AX6: HINMEI_KANA | AY6: HINMEI_KANJI | AZ6: LOT_NO_SHITEI_KBN | BA6: LOT_NO | BB6: JUYOKA_KIGYO_CD | BC6: JUYOKA_BMN_CD | BD6: JUYOKA_NM_KANA | BE6: JUYOKA_NM_KANJI | BF6: JUYOKA_CHUMON_NO | BG6: NIJITEN_CODE | BH6: NIJITEN_NM_KANA | BI6: NIJITEN_NM_KANJI | BJ6: SANJITEN_KIGYO_CD | BK6: SANJITEN_BMN_CD | BL6: SANJITEN_NM_KANA | BM6: SANJITEN_NM_KANJI | BN6: KESSAI_JOKEN_SHIMEKIRI_D | BO6: KESSAI_JOKEN_KISAN_D | BP6: KESSAI_JOKEN_SHUDAN | BQ6: KESSAI_JOKEN_MANKI_D | BR6: KESSAI_JOKEN_KIJUN | BS6: KESSAI_JOKEN | BT6: SURYO_CONFIRM_KBN | BU6: HAN_TANK | BV6: TANK_UNIT | BW6: TANK_KBN | BX6: KOSEN_KBN | BY6: KOSEN_TANK | BZ6: KOSEN_GAKU | CA6: NIJITEN_KOSEN_KBN | CB6: NIJITEN_KOSEN_TANK | CC6: NIJITEN_KOSEN_GAKU | CD6: NNY_KIGYO_CD | CE6: NNY_BMN_CD | CF6: NNY_NM_KANA | CG6: NNY_NM_KANJI | CH6: UKEWATASHI_JOKEN | CI6: UKEWATASHI_BASHO_ADDRK | CJ6: UKEWATASHI_BASHO_ADDR | CK6: CHIKU_CD | CL6: ZIP | CM6: TEL | CN6: FAX | CO6: KIBO_NONYU_D | CP6: KIBO_NONYU_TM | CQ6: KIBO_NONYU_COMMENT | CR6: NONYU_YMD | CS6: NONYU_YOKEN_KANA | CT6: NONYU_YOKEN_KANJI | CU6: PAY_GAKU | CV6: PAY_SEIRI_NO | CW6: BANK_INF | CX6: CHUMON_SURYO | CY6: CHUMON_HAN_KOSU | CZ6: CHUMON_SURYO_UNIT | DA6: HAN_KOSU | DB6: GAKU_CLC_SURYO | DC6: NISUGATA_CD | DD6: NISUGATA_NM | DE6: YORYO | DF6: HAN_GAKU | DG6: SEIKYU_GAKU | DH6: SHOHIZEI_GAKU | DI6: ZEIKOMI_SEIKYU_GAKU | DJ6: TANK_GAKU_KBN | DK6: TORIHIKI_KBN | DL6: SOKYU_KBN | DM6: SHUKKA_SEIKYU_KBN | DN6: KAZEI_KBN | DO6: BACK_ORDER_KBN | DP6: KEIJO_YMD | DQ6: TEKIYO_TAX_RATE | DR6: SHUKKA_SEIKYU_REG_NO | DS6: HEMPIN_SHISAN_MOTO_JOTO_KEIJO_D | DT6: SHUKKA_SEIKYU_YMD_YOTEI | DU6: SHUKKA_HOKOKU_NO | DV6: SHUKKA_SEIKYU_NO | DW6: SHUKKA_BASHO | DX6: SHUKKA_SASHIZU_COMMENT_KANA | DY6: SHUKKA_SASHIZU_COMMENT_KANJI | DZ6: YUSO_SHUDAN | EA6: YUSO_SHASHU | EB6: HACSHA_INF | EC6: JUC_INF | ED6: DOM_EXP_KBN | EE6: ERR_RIYU | EF6: ERR_COMMENT_KANA | EG6: ERR_COMMENT_KANJI | EH6: SEIKYU_CHK_KBN | EI6: YOBI | EJ6: YOBI_KANJI | EK6: FILLER | EL6: COLUMN_1 | EM6: FUNC_UKETSUKE_NO
C7: 【テスト結果】
B8: =ROW()-6 -> 2 | C8: No34,35,39 | D8: =IF(連携ファイル分割!$D5="","",MIDB(連携ファイル分割!$D5,連携ファイル_項目分割!D$3,連携ファイル_項目分割!D$4)) -> S501708785 | E8: =IF(連携ファイル分割!$D5="","",MIDB(連携ファイル分割!$D5,連携ファイル_項目分割!E$3,連携ファイル_項目分割!E$4)) -> 0 | F8: =IF(連携ファイル分割!$D5="","",MIDB(連携ファイル分割!$D5,連携ファイル_項目分割!F$3,連携ファイル_項目分割!F$4)) -> * | G8: =IF(連携ファイル分割!$D5="","",MIDB(連携ファイル分割!$D5,連携ファイル_項目分割!G$3,連携ファイル_項目分割!G$4)) -> SA05441021 | H8: =IF(連携ファイル分割!$D5="","",MIDB(連携ファイル分割!$D5,連携ファイル_項目分割!H$3,連携ファイル_項目分割!H$4)) -> 0 | I8: =IF(連携ファイル分割!$D5="","",MIDB(連携ファイル分割!$D5,連携ファイル_項目分割!I$3,連携ファイル_項目分割!I$4)) -> 0 | J8: =IF(連携ファイル分割!$D5="","",MIDB(連携ファイル分割!$D5,連携ファイル_項目分割!J$3,連携ファイル_項目分割!J$4)) -> SA05441021 | K8: =IF(連携ファイル分割!$D5="","",MIDB(連携ファイル分割!$D5,連携ファイル_項目分割!K$3,連携ファイル_項目分割!K$4)) -> # | ... EM8: =IF(連携ファイル分割!$D5="","",MIDB(連携ファイル分割!$D5,連携ファイル_項目分割!EM$3,連携ファイル_項目分割!EM$4)) -> 631242
B9: =ROW()-6 -> 3 | C9: No34,35,40 | D9: =IF(連携ファイル分割!$D6="","",MIDB(連携ファイル分割!$D6,連携ファイル_項目分割!D$3,連携ファイル_項目分割!D$4)) -> S501708784 | E9: =IF(連携ファイル分割!$D6="","",MIDB(連携ファイル分割!$D6,連携ファイル_項目分割!E$3,連携ファイル_項目分割!E$4)) -> 1 | F9: =IF(連携ファイル分割!$D6="","",MIDB(連携ファイル分割!$D6,連携ファイル_項目分割!F$3,連携ファイル_項目分割!F$4)) -> * | G9: =IF(連携ファイル分割!$D6="","",MIDB(連携ファイル分割!$D6,連携ファイル_項目分割!G$3,連携ファイル_項目分割!G$4)) -> SA05441022 | H9: =IF(連携ファイル分割!$D6="","",MIDB(連携ファイル分割!$D6,連携ファイル_項目分割!H$3,連携ファイル_項目分割!H$4)) -> 0 | I9: =IF(連携ファイル分割!$D6="","",MIDB(連携ファイル分割!$D6,連携ファイル_項目分割!I$3,連携ファイル_項目分割!I$4)) -> 0 | J9: =IF(連携ファイル分割!$D6="","",MIDB(連携ファイル分割!$D6,連携ファイル_項目分割!J$3,連携ファイル_項目分割!J$4)) -> SA05441022 | K9: =IF(連携ファイル分割!$D6="","",MIDB(連携ファイル分割!$D6,連携ファイル_項目分割!K$3,連携ファイル_項目分割!K$4)) -> # | ... EM9: =IF(連携ファイル分割!$D6="","",MIDB(連携ファイル分割!$D6,連携ファイル_項目分割!EM$3,連携ファイル_項目分割!EM$4)) -> 631242
B10: =ROW()-6 -> 4 | C10: No34,35,41 | D10: =IF(連携ファイル分割!$D7="","",MIDB(連携ファイル分割!$D7,連携ファイル_項目分割!D$3,連携ファイル_項目分割!D$4)) -> S501707765 | E10: =IF(連携ファイル分割!$D7="","",MIDB(連携ファイル分割!$D7,連携ファイル_項目分割!E$3,連携ファイル_項目分割!E$4)) -> 2 | F10: =IF(連携ファイル分割!$D7="","",MIDB(連携ファイル分割!$D7,連携ファイル_項目分割!F$3,連携ファイル_項目分割!F$4)) -> * | G10: =IF(連携ファイル分割!$D7="","",MIDB(連携ファイル分割!$D7,連携ファイル_項目分割!G$3,連携ファイル_項目分割!G$4)) -> SA05441023 | H10: =IF(連携ファイル分割!$D7="","",MIDB(連携ファイル分割!$D7,連携ファイル_項目分割!H$3,連携ファイル_項目分割!H$4)) -> 0 | I10: =IF(連携ファイル分割!$D7="","",MIDB(連携ファイル分割!$D7,連携ファイル_項目分割!I$3,連携ファイル_項目分割!I$4)) -> 0 | J10: =IF(連携ファイル分割!$D7="","",MIDB(連携ファイル分割!$D7,連携ファイル_項目分割!J$3,連携ファイル_項目分割!J$4)) -> SA05441023 | K10: =IF(連携ファイル分割!$D7="","",MIDB(連携ファイル分割!$D7,連携ファイル_項目分割!K$3,連携ファイル_項目分割!K$4)) -> # | ... EM10: =IF(連携ファイル分割!$D7="","",MIDB(連携ファイル分割!$D7,連携ファイル_項目分割!EM$3,連携ファイル_項目分割!EM$4)) -> 631242
B11: =ROW()-6 -> 5 | C11: No34,35,42 | D11: =IF(連携ファイル分割!$D8="","",MIDB(連携ファイル分割!$D8,連携ファイル_項目分割!D$3,連携ファイル_項目分割!D$4)) -> S501708790 | E11: =IF(連携ファイル分割!$D8="","",MIDB(連携ファイル分割!$D8,連携ファイル_項目分割!E$3,連携ファイル_項目分割!E$4)) -> 3 | F11: =IF(連携ファイル分割!$D8="","",MIDB(連携ファイル分割!$D8,連携ファイル_項目分割!F$3,連携ファイル_項目分割!F$4)) -> * | G11: =IF(連携ファイル分割!$D8="","",MIDB(連携ファイル分割!$D8,連携ファイル_項目分割!G$3,連携ファイル_項目分割!G$4)) -> SA05441024 | H11: =IF(連携ファイル分割!$D8="","",MIDB(連携ファイル分割!$D8,連携ファイル_項目分割!H$3,連携ファイル_項目分割!H$4)) -> 0 | I11: =IF(連携ファイル分割!$D8="","",MIDB(連携ファイル分割!$D8,連携ファイル_項目分割!I$3,連携ファイル_項目分割!I$4)) -> 0 | J11: =IF(連携ファイル分割!$D8="","",MIDB(連携ファイル分割!$D8,連携ファイル_項目分割!J$3,連携ファイル_項目分割!J$4)) -> SA05441024 | K11: =IF(連携ファイル分割!$D8="","",MIDB(連携ファイル分割!$D8,連携ファイル_項目分割!K$3,連携ファイル_項目分割!K$4)) -> # | ... EM11: =IF(連携ファイル分割!$D8="","",MIDB(連携ファイル分割!$D8,連携ファイル_項目分割!EM$3,連携ファイル_項目分割!EM$4)) -> 631242
B12: =ROW()-6 -> 6 | C12: No34,35,43 | D12: =IF(連携ファイル分割!$D9="","",MIDB(連携ファイル分割!$D9,連携ファイル_項目分割!D$3,連携ファイル_項目分割!D$4)) -> S501708799 | E12: =IF(連携ファイル分割!$D9="","",MIDB(連携ファイル分割!$D9,連携ファイル_項目分割!E$3,連携ファイル_項目分割!E$4)) -> 4 | F12: =IF(連携ファイル分割!$D9="","",MIDB(連携ファイル分割!$D9,連携ファイル_項目分割!F$3,連携ファイル_項目分割!F$4)) -> * | G12: =IF(連携ファイル分割!$D9="","",MIDB(連携ファイル分割!$D9,連携ファイル_項目分割!G$3,連携ファイル_項目分割!G$4)) -> SA05444437 | H12: =IF(連携ファイル分割!$D9="","",MIDB(連携ファイル分割!$D9,連携ファイル_項目分割!H$3,連携ファイル_項目分割!H$4)) -> 0 | I12: =IF(連携ファイル分割!$D9="","",MIDB(連携ファイル分割!$D9,連携ファイル_項目分割!I$3,連携ファイル_項目分割!I$4)) -> 0 | J12: =IF(連携ファイル分割!$D9="","",MIDB(連携ファイル分割!$D9,連携ファイル_項目分割!J$3,連携ファイル_項目分割!J$4)) -> SA05444437 | K12: =IF(連携ファイル分割!$D9="","",MIDB(連携ファイル分割!$D9,連携ファイル_項目分割!K$3,連携ファイル_項目分割!K$4)) -> # | ... EM12: =IF(連携ファイル分割!$D9="","",MIDB(連携ファイル分割!$D9,連携ファイル_項目分割!EM$3,連携ファイル_項目分割!EM$4)) -> 631242
B13: =ROW()-6 -> 7 | C13: No34,35,44 | D13: =IF(連携ファイル分割!$D10="","",MIDB(連携ファイル分割!$D10,連携ファイル_項目分割!D$3,連携ファイル_項目分割!D$4)) -> S501708798 | E13: =IF(連携ファイル分割!$D10="","",MIDB(連携ファイル分割!$D10,連携ファイル_項目分割!E$3,連携ファイル_項目分割!E$4)) -> 5 | F13: =IF(連携ファイル分割!$D10="","",MIDB(連携ファイル分割!$D10,連携ファイル_項目分割!F$3,連携ファイル_項目分割!F$4)) -> * | G13: =IF(連携ファイル分割!$D10="","",MIDB(連携ファイル分割!$D10,連携ファイル_項目分割!G$3,連携ファイル_項目分割!G$4)) -> SA05444438 | H13: =IF(連携ファイル分割!$D10="","",MIDB(連携ファイル分割!$D10,連携ファイル_項目分割!H$3,連携ファイル_項目分割!H$4)) -> 0 | I13: =IF(連携ファイル分割!$D10="","",MIDB(連携ファイル分割!$D10,連携ファイル_項目分割!I$3,連携ファイル_項目分割!I$4)) -> 0 | J13: =IF(連携ファイル分割!$D10="","",MIDB(連携ファイル分割!$D10,連携ファイル_項目分割!J$3,連携ファイル_項目分割!J$4)) -> SA05444438 | K13: =IF(連携ファイル分割!$D10="","",MIDB(連携ファイル分割!$D10,連携ファイル_項目分割!K$3,連携ファイル_項目分割!K$4)) -> # | ... EM13: =IF(連携ファイル分割!$D10="","",MIDB(連携ファイル分割!$D10,連携ファイル_項目分割!EM$3,連携ファイル_項目分割!EM$4)) -> 631242
B14: =ROW()-6 -> 8 | C14: No34,35,45 | D14: =IF(連携ファイル分割!$D11="","",MIDB(連携ファイル分割!$D11,連携ファイル_項目分割!D$3,連携ファイル_項目分割!D$4)) -> S501708797 | E14: =IF(連携ファイル分割!$D11="","",MIDB(連携ファイル分割!$D11,連携ファイル_項目分割!E$3,連携ファイル_項目分割!E$4)) -> 6 | F14: =IF(連携ファイル分割!$D11="","",MIDB(連携ファイル分割!$D11,連携ファイル_項目分割!F$3,連携ファイル_項目分割!F$4)) -> * | G14: =IF(連携ファイル分割!$D11="","",MIDB(連携ファイル分割!$D11,連携ファイル_項目分割!G$3,連携ファイル_項目分割!G$4)) -> SA05444439 | H14: =IF(連携ファイル分割!$D11="","",MIDB(連携ファイル分割!$D11,連携ファイル_項目分割!H$3,連携ファイル_項目分割!H$4)) -> 0 | I14: =IF(連携ファイル分割!$D11="","",MIDB(連携ファイル分割!$D11,連携ファイル_項目分割!I$3,連携ファイル_項目分割!I$4)) -> 0 | J14: =IF(連携ファイル分割!$D11="","",MIDB(連携ファイル分割!$D11,連携ファイル_項目分割!J$3,連携ファイル_項目分割!J$4)) -> SA05444439 | K14: =IF(連携ファイル分割!$D11="","",MIDB(連携ファイル分割!$D11,連携ファイル_項目分割!K$3,連携ファイル_項目分割!K$4)) -> # | ... EM14: =IF(連携ファイル分割!$D11="","",MIDB(連携ファイル分割!$D11,連携ファイル_項目分割!EM$3,連携ファイル_項目分割!EM$4)) -> 631242
B15: =ROW()-6 -> 9 | C15: No34,35,46 | D15: =IF(連携ファイル分割!$D12="","",MIDB(連携ファイル分割!$D12,連携ファイル_項目分割!D$3,連携ファイル_項目分割!D$4)) | E15: =IF(連携ファイル分割!$D12="","",MIDB(連携ファイル分割!$D12,連携ファイル_項目分割!E$3,連携ファイル_項目分割!E$4)) | F15: =IF(連携ファイル分割!$D12="","",MIDB(連携ファイル分割!$D12,連携ファイル_項目分割!F$3,連携ファイル_項目分割!F$4)) | G15: =IF(連携ファイル分割!$D12="","",MIDB(連携ファイル分割!$D12,連携ファイル_項目分割!G$3,連携ファイル_項目分割!G$4)) | H15: =IF(連携ファイル分割!$D12="","",MIDB(連携ファイル分割!$D12,連携ファイル_項目分割!H$3,連携ファイル_項目分割!H$4)) | I15: =IF(連携ファイル分割!$D12="","",MIDB(連携ファイル分割!$D12,連携ファイル_項目分割!I$3,連携ファイル_項目分割!I$4)) | J15: =IF(連携ファイル分割!$D12="","",MIDB(連携ファイル分割!$D12,連携ファイル_項目分割!J$3,連携ファイル_項目分割!J$4)) | K15: =IF(連携ファイル分割!$D12="","",MIDB(連携ファイル分割!$D12,連携ファイル_項目分割!K$3,連携ファイル_項目分割!K$4)) | ... EM15: =IF(連携ファイル分割!$D12="","",MIDB(連携ファイル分割!$D12,連携ファイル_項目分割!EM$3,連携ファイル_項目分割!EM$4))
B16: =ROW()-6 -> 10 | C16: No34,35,47 | D16: =IF(連携ファイル分割!$D13="","",MIDB(連携ファイル分割!$D13,連携ファイル_項目分割!D$3,連携ファイル_項目分割!D$4)) | E16: =IF(連携ファイル分割!$D13="","",MIDB(連携ファイル分割!$D13,連携ファイル_項目分割!E$3,連携ファイル_項目分割!E$4)) | F16: =IF(連携ファイル分割!$D13="","",MIDB(連携ファイル分割!$D13,連携ファイル_項目分割!F$3,連携ファイル_項目分割!F$4)) | G16: =IF(連携ファイル分割!$D13="","",MIDB(連携ファイル分割!$D13,連携ファイル_項目分割!G$3,連携ファイル_項目分割!G$4)) | H16: =IF(連携ファイル分割!$D13="","",MIDB(連携ファイル分割!$D13,連携ファイル_項目分割!H$3,連携ファイル_項目分割!H$4)) | I16: =IF(連携ファイル分割!$D13="","",MIDB(連携ファイル分割!$D13,連携ファイル_項目分割!I$3,連携ファイル_項目分割!I$4)) | J16: =IF(連携ファイル分割!$D13="","",MIDB(連携ファイル分割!$D13,連携ファイル_項目分割!J$3,連携ファイル_項目分割!J$4)) | K16: =IF(連携ファイル分割!$D13="","",MIDB(連携ファイル分割!$D13,連携ファイル_項目分割!K$3,連携ファイル_項目分割!K$4)) | ... EM16: =IF(連携ファイル分割!$D13="","",MIDB(連携ファイル分割!$D13,連携ファイル_項目分割!EM$3,連携ファイル_項目分割!EM$4))
B17: =ROW()-6 -> 11 | C17: No34,35,48 | D17: =IF(連携ファイル分割!$D14="","",MIDB(連携ファイル分割!$D14,連携ファイル_項目分割!D$3,連携ファイル_項目分割!D$4)) | E17: =IF(連携ファイル分割!$D14="","",MIDB(連携ファイル分割!$D14,連携ファイル_項目分割!E$3,連携ファイル_項目分割!E$4)) | F17: =IF(連携ファイル分割!$D14="","",MIDB(連携ファイル分割!$D14,連携ファイル_項目分割!F$3,連携ファイル_項目分割!F$4)) | G17: =IF(連携ファイル分割!$D14="","",MIDB(連携ファイル分割!$D14,連携ファイル_項目分割!G$3,連携ファイル_項目分割!G$4)) | H17: =IF(連携ファイル分割!$D14="","",MIDB(連携ファイル分割!$D14,連携ファイル_項目分割!H$3,連携ファイル_項目分割!H$4)) | I17: =IF(連携ファイル分割!$D14="","",MIDB(連携ファイル分割!$D14,連携ファイル_項目分割!I$3,連携ファイル_項目分割!I$4)) | J17: =IF(連携ファイル分割!$D14="","",MIDB(連携ファイル分割!$D14,連携ファイル_項目分割!J$3,連携ファイル_項目分割!J$4)) | K17: =IF(連携ファイル分割!$D14="","",MIDB(連携ファイル分割!$D14,連携ファイル_項目分割!K$3,連携ファイル_項目分割!K$4)) | ... EM17: =IF(連携ファイル分割!$D14="","",MIDB(連携ファイル分割!$D14,連携ファイル_項目分割!EM$3,連携ファイル_項目分割!EM$4))
B18: =ROW()-6 -> 12 | C18: No34,35,49 | D18: =IF(連携ファイル分割!$D15="","",MIDB(連携ファイル分割!$D15,連携ファイル_項目分割!D$3,連携ファイル_項目分割!D$4)) | E18: =IF(連携ファイル分割!$D15="","",MIDB(連携ファイル分割!$D15,連携ファイル_項目分割!E$3,連携ファイル_項目分割!E$4)) | F18: =IF(連携ファイル分割!$D15="","",MIDB(連携ファイル分割!$D15,連携ファイル_項目分割!F$3,連携ファイル_項目分割!F$4)) | G18: =IF(連携ファイル分割!$D15="","",MIDB(連携ファイル分割!$D15,連携ファイル_項目分割!G$3,連携ファイル_項目分割!G$4)) | H18: =IF(連携ファイル分割!$D15="","",MIDB(連携ファイル分割!$D15,連携ファイル_項目分割!H$3,連携ファイル_項目分割!H$4)) | I18: =IF(連携ファイル分割!$D15="","",MIDB(連携ファイル分割!$D15,連携ファイル_項目分割!I$3,連携ファイル_項目分割!I$4)) | J18: =IF(連携ファイル分割!$D15="","",MIDB(連携ファイル分割!$D15,連携ファイル_項目分割!J$3,連携ファイル_項目分割!J$4)) | K18: =IF(連携ファイル分割!$D15="","",MIDB(連携ファイル分割!$D15,連携ファイル_項目分割!K$3,連携ファイル_項目分割!K$4)) | ... EM18: =IF(連携ファイル分割!$D15="","",MIDB(連携ファイル分割!$D15,連携ファイル_項目分割!EM$3,連携ファイル_項目分割!EM$4))
B19: =ROW()-6 -> 13 | C19: No34,35,50 | D19: =IF(連携ファイル分割!$D16="","",MIDB(連携ファイル分割!$D16,連携ファイル_項目分割!D$3,連携ファイル_項目分割!D$4)) | E19: =IF(連携ファイル分割!$D16="","",MIDB(連携ファイル分割!$D16,連携ファイル_項目分割!E$3,連携ファイル_項目分割!E$4)) | F19: =IF(連携ファイル分割!$D16="","",MIDB(連携ファイル分割!$D16,連携ファイル_項目分割!F$3,連携ファイル_項目分割!F$4)) | G19: =IF(連携ファイル分割!$D16="","",MIDB(連携ファイル分割!$D16,連携ファイル_項目分割!G$3,連携ファイル_項目分割!G$4)) | H19: =IF(連携ファイル分割!$D16="","",MIDB(連携ファイル分割!$D16,連携ファイル_項目分割!H$3,連携ファイル_項目分割!H$4)) | I19: =IF(連携ファイル分割!$D16="","",MIDB(連携ファイル分割!$D16,連携ファイル_項目分割!I$3,連携ファイル_項目分割!I$4)) | J19: =IF(連携ファイル分割!$D16="","",MIDB(連携ファイル分割!$D16,連携ファイル_項目分割!J$3,連携ファイル_項目分割!J$4)) | K19: =IF(連携ファイル分割!$D16="","",MIDB(連携ファイル分割!$D16,連携ファイル_項目分割!K$3,連携ファイル_項目分割!K$4)) | ... EM19: =IF(連携ファイル分割!$D16="","",MIDB(連携ファイル分割!$D16,連携ファイル_項目分割!EM$3,連携ファイル_項目分割!EM$4))
... B49: =ROW()-6 -> 43 | C49: No34,35,80 | D49: =IF(連携ファイル分割!$D46="","",MIDB(連携ファイル分割!$D46,連携ファイル_項目分割!D$3,連携ファイル_項目分割!D$4)) | E49: =IF(連携ファイル分割!$D46="","",MIDB(連携ファイル分割!$D46,連携ファイル_項目分割!E$3,連携ファイル_項目分割!E$4)) | F49: =IF(連携ファイル分割!$D46="","",MIDB(連携ファイル分割!$D46,連携ファイル_項目分割!F$3,連携ファイル_項目分割!F$4)) | G49: =IF(連携ファイル分割!$D46="","",MIDB(連携ファイル分割!$D46,連携ファイル_項目分割!G$3,連携ファイル_項目分割!G$4)) | H49: =IF(連携ファイル分割!$D46="","",MIDB(連携ファイル分割!$D46,連携ファイル_項目分割!H$3,連携ファイル_項目分割!H$4)) | I49: =IF(連携ファイル分割!$D46="","",MIDB(連携ファイル分割!$D46,連携ファイル_項目分割!I$3,連携ファイル_項目分割!I$4)) | J49: =IF(連携ファイル分割!$D46="","",MIDB(連携ファイル分割!$D46,連携ファイル_項目分割!J$3,連携ファイル_項目分割!J$4)) | K49: =IF(連携ファイル分割!$D46="","",MIDB(連携ファイル分割!$D46,連携ファイル_項目分割!K$3,連携ファイル_項目分割!K$4)) | ... EM49: =IF(連携ファイル分割!$D46="","",MIDB(連携ファイル分割!$D46,連携ファイル_項目分割!EM$3,連携ファイル_項目分割!EM$4))

Sheet 請求確認_送信ファイル
A1: 請求確認_送信ファイル出力確認
B3: No. | C3: テストNo | D3: 送信ファイルデータ
C4: 【テスト結果】 | D4: DNKA1301を以下に貼り付ける
B5: =B4+1 -> 1 | C5: No34,35,39 | D5: JPCA0102S1720101913000010114876000001
B6: =B5+1 -> 2 | C6: No34,35,39
B7: =B6+1 -> 3 | C7: No34,35,39
B8: =B7+1 -> 4 | C8: No34,35,39
B9: =B8+1 -> 5 | C9: No34,35,39
B10: =B9+1 -> 6
B11: =B10+1 -> 7
B12: =B11+1 -> 8
B13: =B12+1 -> 9
B14: =B13+1 -> 10
B15: =B14+1 -> 11
B16: =B15+1 -> 12
B17: =B16+1 -> 13
B18: =B17+1 -> 14
B19: =B18+1 -> 15
B20: =B19+1 -> 16
B21: =B20+1 -> 17
... B46: =B45+1 -> 42

Sheet 請求確認_送信ファイル_項目分割
A1: 項目分割
C3: 開始位置 | D3: 1 | E3: 2 | F3: 10 | G3: 11 | H3: 15 | I3: 27 | J3: 39 | K3: 43 | L3: 44 | M3: 50 | N3: 56 | O3: 57 | P3: 63 | Q3: 69 | R3: 75 | S3: 81 | T3: 87 | U3: 93 | V3: 99 | W3: 105 | X3: 111 | Y3: 117 | Z3: 127 | AA3: 133 | AB3: 143 | AC3: 149 | AD3: 153 | AE3: 154 | AF3: 155 | AG3: 156 | AH3: 200 | AI3: 244 | AJ3: 254 | AK3: 260 | AL3: 264 | AM3: 270 | AN3: 271 | AO3: 272 | AP3: 277 | AQ3: 347 | AR3: 417 | AS3: 418 | AT3: 428 | AU3: 440 | AV3: 480 | AW3: 520 | AX3: 530 | AY3: 542 | AZ3: 582 | BA3: 622 | BB3: 634 | BC3: 674 | BD3: 714 | BE3: 720 | BF3: 726 | BG3: 727 | BH3: 733 | BI3: 734 | BJ3: 749 | BK3: 750 | BL3: 765 | BM3: 768 | BN3: 769 | BO3: 770 | BP3: 785 | BQ3: 799 | BR3: 800 | BS3: 815 | BT3: 829 | BU3: 841 | BV3: 881 | BW3: 921 | BX3: 923 | BY3: 997 | BZ3: 1071 | CA3: 1082 | CB3: 1089 | CC3: 1101 | CD3: 1113 | CE3: 1119 | CF3: 1123 | CG3: 1133 | CH3: 1139 | CI3: 1183 | CJ3: 1227 | CK3: 1241 | CL3: 1253 | CM3: 1265 | CN3: 1272 | CO3: 1302 | CP3: 1309 | CQ3: 1339 | CR3: 1346 | CS3: 1356 | CT3: 1371 | CU3: 1386 | CV3: 1389 | CW3: 1404 | CX3: 1419 | CY3: 1429 | CZ3: 1444 | DA3: 1458 | DB3: 1472 | DC3: 1486 | DD3: 1500 | DE3: 1501 | DF3: 1502 | DG3: 1503 | DH3: 1504 | DI3: 1506 | DJ3: 1507 | DK3: 1511 | DL3: 1517 | DM3: 1542 | DN3: 1552 | DO3: 1557 | DP3: 1601 | DQ3: 1645 | DR3: 1647 | DS3: 1657 | DT3: 1677 | DU3: 1697 | DV3: 1698 | DW3: 1708 | DX3: 1752 | DY3: 1796 | DZ3: 1797 | EA3: 1827 | EB3: 1857
C4: 桁数 | D4: 1 | E4: 8 | F4: 1 | G4: 4 | H4: 12 | I4: 12 | J4: 4 | K4: 1 | L4: 6 | M4: 6 | N4: 1 | O4: 6 | P4: 6 | Q4: 6 | R4: 6 | S4: 6 | T4: 6 | U4: 6 | V4: 6 | W4: 6 | X4: 6 | Y4: 10 | Z4: 6 | AA4: 10 | AB4: 6 | AC4: 4 | AD4: 1 | AE4: 1 | AF4: 1 | AG4: 44 | AH4: 44 | AI4: 10 | AJ4: 6 | AK4: 4 | AL4: 6 | AM4: 1 | AN4: 1 | AO4: 5 | AP4: 70 | AQ4: 70 | AR4: 1 | AS4: 10 | AT4: 12 | AU4: 40 | AV4: 40 | AW4: 10 | AX4: 12 | AY4: 40 | AZ4: 40 | BA4: 12 | BB4: 40 | BC4: 40 | BD4: 6 | BE4: 6 | BF4: 1 | BG4: 6 | BH4: 1 | BI4: 15 | BJ4: 1 | BK4: 15 | BL4: 3 | BM4: 1 | BN4: 1 | BO4: 15 | BP4: 14 | BQ4: 1 | BR4: 15 | BS4: 14 | BT4: 12 | BU4: 40 | BV4: 40 | BW4: 2 | BX4: 74 | BY4: 74 | BZ4: 11 | CA4: 7 | CB4: 12 | CC4: 12 | CD4: 6 | CE4: 4 | CF4: 10 | CG4: 6 | CH4: 44 | CI4: 44 | CJ4: 14 | CK4: 12 | CL4: 12 | CM4: 7 | CN4: 30 | CO4: 7 | CP4: 30 | CQ4: 7 | CR4: 10 | CS4: 15 | CT4: 15 | CU4: 3 | CV4: 15 | CW4: 15 | CX4: 10 | CY4: 15 | CZ4: 14 | DA4: 14 | DB4: 14 | DC4: 14 | DD4: 1 | DE4: 1 | DF4: 1 | DG4: 1 | DH4: 2 | DI4: 1 | DJ4: 4 | DK4: 6 | DL4: 25 | DM4: 10 | DN4: 5 | DO4: 44 | DP4: 44 | DQ4: 2 | DR4: 10 | DS4: 20 | DT4: 20 | DU4: 1 | DV4: 10 | DW4: 44 | DX4: 44 | DY4: 1 | DZ4: 30 | EA4: 30 | EB4: 67
B5: No. | C5: テストNo | D5: リザーブ | E5: BPID | F5: 送受信 | G5: 情報区分 | H5: 自社コード | I5: 相手先コード | J5: データ種別 | K5: 処理区分 | L5: 処理年月日 | M5: 処理時刻 | N5: 赤黒区分 | O5: 発注者企業コード | P5: 発注者部門コード | Q5: 新発注者企業コード | R5: 新発注者部門コード | S5: 受注者企業コード | T5: 受注者部門コード | U5: 請求者企業コード | V5: 請求者部門コード | W5: 支払者企業コード | X5: 支払先部門コード | Y5: 契約番号 | Z5: 実施年月日 | AA5: 注文番号 | AB5: 発注者・注文日 | AC5: 発注者・注文時刻 | AD5: オーダ区分 | AE5: 連絡要否区分 | AF5: 数量指定区分 | AG5: 発注コメント カナ | AH5: 発注コメント 漢字 | AI5: 受注番号 | AJ5: 受注者注文受付日 | AK5: 受注者注文受付時刻 | AL5: 受注者注文確定日 | AM5: 分納区分 | AN5: 受注者処理区分 | AO5: 品名グループ | AP5: 品名（カナ） | AQ5: 品名（漢字） | AR5: ロット番号指定区分 | AS5: ロット番号 | AT5: 需要家コード | AU5: 需要家名称（カナ） | AV5: 需要家名称（漢字） | AW5: 需要家注文番号 | AX5: ２次店コード | AY5: ２次店名称 | AZ5: ２次店名称（漢字） | BA5: ３次店コード | BB5: ３次店名称 | BC5: ３次店名称（漢字） | BD5: 決済条件締切日 | BE5: 決済条件起算日 | BF5: 決済条件手段 | BG5: 決済条件満期日 | BH5: 決済条件基準 | BI5: 決済条件 | BJ5: 数量確定区分 | BK5: 販売単価 | BL5: 単価単位 | BM5: 単価区分 | BN5: 口銭区分 | BO5: 口銭単価 | BP5: 口銭 | BQ5: ２次店口銭区分 | BR5: ２次店口銭単価 | BS5: ２次店口銭 | BT5: 納入先コード | BU5: 納入先名称 | BV5: 納入先名称（漢字） | BW5: 受渡条件 | BX5: 受渡場所住所 | BY5: 受渡場所住所（漢字） | BZ5: 地区コード | CA5: 郵便番号 | CB5: 電話番号 | CC5: ＦＡＸ電話番号 | CD5: 希望納入年月日 | CE5: 希望納入時刻 | CF5: 希望納入コメント | CG5: 納入日（予定） | CH5: 納入要件 | CI5: 納入要件（漢字） | CJ5: 支払金額 | CK5: 支払整理番号 | CL5: 手形（小切手）番号 | CM5: 振出銀行（コード） | CN5: 振出銀行（名称） | CO5: 振込銀行（コード） | CP5: 振込銀行（名称） | CQ5: 口座番号 | CR5: 支払要件 | CS5: 注文数量 | CT5: 注文・販売個数 | CU5: 注文数量単位 | CV5: 販売数量 | CW5: 金額算出数量 | CX5: 荷姿 | CY5: 容量 | CZ5: 販売金額 | DA5: 請求金額 | DB5: 消費税額 | DC5: 税込請求額 | DD5: 単価金額区分 | DE5: 取引区分 | DF5: 遡及区分 | DG5: 出荷請求区分 | DH5: 課税区分 | DI5: バックオーダー区分 | DJ5: 計上年月 | DK5: 出荷年月日（予定） | DL5: 出荷報告番号 | DM5: 出荷請求番号 | DN5: 出荷場所 | DO5: 出荷指図コメント（カナ） | DP5: 出荷指図コメント 漢字 | DQ5: 輸送手段 | DR5: 輸送車輌 | DS5: 発注者情報 | DT5: 受注者情報 | DU5: 国内輸出区分 | DV5: エラー理由 | DW5: エラーコメント | DX5: エラーコメント 漢字 | DY5: 請求確認区分 | DZ5: 予備欄 | EA5: 予備欄（漢字） | EB5: 空白
D6: RESERVE | E6: BPID | F6: SND_RCV | G6: INF_KBN | H6: JISHA_CD | I6: AITE_SAKI_CD | J6: DATA_SBT | K6: FUNC_KBN | L6: FUNC_YMD | M6: FUNC_TM | N6: AKAKURO_KBN | O6: HACSHA_KIGYO_CD | P6: HACSHA_BMN_CD | Q6: NEW_HACSHA_KIGYO_CD | R6: NEW_HACSHA_BMN_CD | S6: JUC_KIGYO_CD | T6: JUC_BMN_CD | U6: SEIKYU_KIGYO_CD | V6: SEIKYU_BMN_CD | W6: PAY_KIGYO_CD | X6: PAY_BMN_CD | Y6: KEIYAKU_NO | Z6: JISSHI_YMD | AA6: CHUMON_NO | AB6: HACSHA_CHUMON_D | AC6: HACSHA_CHUMON_TM | AD6: ORDER_KBN | AE6: RENRAKU_YN_KBN | AF6: SURYO_SHITEI_KBN | AG6: HAC_COMMENT_KANA | AH6: HAC_COMMENT_KANJI | AI6: JUC_NO | AJ6: JUC_CHUMON_UKETSUKE_DT | AK6: JUC_CHUMON_UKETSUKE_TM | AL6: JUC_CHUMON_CONFIRM_D | AM6: BUNNO_KBN | AN6: JUC_FUNC_KBN | AO6: HINMEI_GROUP | AP6: HINMEI_KANA | AQ6: HINMEI_KANJI | AR6: LOT_NO_SHITEI_KBN | AS6: LOT_NO | AT6: JUYOKA_CD | AU6: JUYOKA_NM_KANA | AV6: JUYOKA_NM_KANJI | AW6: JUYOKA_CHUMON_NO | AX6: NIJITEN_CD | AY6: NIJITEN_NM_KANA | AZ6: NIJITEN_NM_KANJI | BA6: SANJITEN_CD | BB6: SANJITEN_NM_KANA | BC6: SANJITEN_NM_KANJI | BD6: KESSAI_JOKEN_SHIMEKIRI_D | BE6: KESSAI_JOKEN_KISAN_D | BF6: KESSAI_JOKEN_SHUDAN | BG6: KESSAI_JOKEN_MANKI_D | BH6: KESSAI_JOKEN_KIJUN | BI6: KESSAI_JOKEN | BJ6: SURYO_CONFIRM_KBN | BK6: HAN_TANK | BL6: TANK_UNIT | BM6: TANK_KBN | BN6: KOSEN_KBN | BO6: KOSEN_TANK | BP6: KOSEN | BQ6: NIJITEN_KOSEN_KBN | BR6: NIJITEN_KOSEN_TANK | BS6: NIJITEN_KOSEN | BT6: NNY_CD | BU6: NNY_NM | BV6: NNY_NM_KANJI | BW6: UKEWATASHI_JOKEN | BX6: UKEWATASHI_BASHO_ADDRK | BY6: UKEWATASHI_BASHO_ADDR | BZ6: CHIKU_CD | CA6: ZIP | CB6: TEL | CC6: FAX_TEL | CD6: KIBO_NONYU_YMD | CE6: KIBO_NONYU_TM | CF6: KIBO_NONYU_COMMENT | CG6: NNY_NM_D_YOTEI | CH6: NONYU_YOKEN_KANA | CI6: NONYU_YOKEN_KANJI | CJ6: PAY_GAKU | CK6: PAY_SEIRI_NO | CL6: TEGATA_NO_KOGITTE | CM6: ISSUE_BANK_CD | CN6: ISSUE_BANK_NM | CO6: FURIKOMI_BANK_CD | CP6: FURIKOMI_BANK_NM | CQ6: KOZA_NO | CR6: PAY_YOKEN | CS6: CHUMON_SURYO | CT6: CHUMON_HAN_KOSU | CU6: CHUMON_SURYO_UNIT | CV6: HAN_SURYO | CW6: GAKU_CLC_SURYO | CX6: NISUGATA | CY6: YORYO | CZ6: HAN_GAKU | DA6: SEIKYU_GAKU | DB6: SHOHIZEI_GAKU | DC6: ZEIKOMI_SEIKYU_GAKU | DD6: TANK_GAKU_KBN | DE6: TORIHIKI_KBN | DF6: SOKYU_KBN | DG6: SHUKKA_SEIKYU_KBN | DH6: KAZEI_KBN | DI6: BACK_ORDER_KBN | DJ6: KEIJO_YM | DK6: SHUKKA_YMD_YOTEI | DL6: SHUKKA_HOKOKU_NO | DM6: SHUKKA_SEIKYU_NO | DN6: SHUKKA_BASHO | DO6: SHUKKA_SASHIZU_COMMENT_KANA | DP6: SHUKKA_SASHIZU_COMMENT_KANJI | DQ6: YUSO_SHUDAN | DR6: YUSO_SHASHU | DS6: HACSHA_INF | DT6: JUC_INF | DU6: DOM_EXP_KBN | DV6: ERR_RIYU | DW6: ERR_COMMENT_KANA | DX6: ERR_COMMENT_KANJI | DY6: SEIKYU_CHK_KBN | DZ6: YOBI_KANA | EA6: YOBI_KANJI | EB6: FILLER
D7: DNKA1301を以下に貼り付ける
B8: =ROW()-6 -> 2 | C8: =IF(請求確認_送信ファイル!C5="","",請求確認_送信ファイル!C5) -> No34,35,39 | D8: =IF(請求確認_送信ファイル!$D5="","",MIDB(請求確認_送信ファイル!$D5,請求確認_送信ファイル_項目分割!D$3,請求確認_送信ファイル_項目分割!D$4)) | E8: =IF(請求確認_送信ファイル!$D5="","",MIDB(請求確認_送信ファイル!$D5,請求確認_送信ファイル_項目分割!E$3,請求確認_送信ファイル_項目分割!E$4)) -> JPCA0102 | F8: =IF(請求確認_送信ファイル!$D5="","",MIDB(請求確認_送信ファイル!$D5,請求確認_送信ファイル_項目分割!F$3,請求確認_送信ファイル_項目分割!F$4)) -> S | G8: =IF(請求確認_送信ファイル!$D5="","",MIDB(請求確認_送信ファイル!$D5,請求確認_送信ファイル_項目分割!G$3,請求確認_送信ファイル_項目分割!G$4)) -> 1720 | H8: =IF(請求確認_送信ファイル!$D5="","",MIDB(請求確認_送信ファイル!$D5,請求確認_送信ファイル_項目分割!H$3,請求確認_送信ファイル_項目分割!H$4)) -> 101913000010 | I8: =IF(請求確認_送信ファイル!$D5="","",MIDB(請求確認_送信ファイル!$D5,請求確認_送信ファイル_項目分割!I$3,請求確認_送信ファイル_項目分割!I$4)) -> 114876000001 | J8: =IF(請求確認_送信ファイル!$D5="","",MIDB(請求確認_送信ファイル!$D5,請求確認_送信ファイル_項目分割!J$3,請求確認_送信ファイル_項目分割!J$4)) | K8: =IF(請求確認_送信ファイル!$D5="","",MIDB(請求確認_送信ファイル!$D5,請求確認_送信ファイル_項目分割!K$3,請求確認_送信ファイル_項目分割!K$4)) | ... EB8: =IF(請求確認_送信ファイル!$D5="","",MIDB(請求確認_送信ファイル!$D5,請求確認_送信ファイル_項目分割!EB$3,請求確認_送信ファイル_項目分割!EB$4))
B9: =ROW()-6 -> 3 | C9: =IF(請求確認_送信ファイル!C6="","",請求確認_送信ファイル!C6) -> No34,35,39 | D9: =IF(請求確認_送信ファイル!$D6="","",MIDB(請求確認_送信ファイル!$D6,請求確認_送信ファイル_項目分割!D$3,請求確認_送信ファイル_項目分割!D$4)) | E9: =IF(請求確認_送信ファイル!$D6="","",MIDB(請求確認_送信ファイル!$D6,請求確認_送信ファイル_項目分割!E$3,請求確認_送信ファイル_項目分割!E$4)) | F9: =IF(請求確認_送信ファイル!$D6="","",MIDB(請求確認_送信ファイル!$D6,請求確認_送信ファイル_項目分割!F$3,請求確認_送信ファイル_項目分割!F$4)) | G9: =IF(請求確認_送信ファイル!$D6="","",MIDB(請求確認_送信ファイル!$D6,請求確認_送信ファイル_項目分割!G$3,請求確認_送信ファイル_項目分割!G$4)) | H9: =IF(請求確認_送信ファイル!$D6="","",MIDB(請求確認_送信ファイル!$D6,請求確認_送信ファイル_項目分割!H$3,請求確認_送信ファイル_項目分割!H$4)) | I9: =IF(請求確認_送信ファイル!$D6="","",MIDB(請求確認_送信ファイル!$D6,請求確認_送信ファイル_項目分割!I$3,請求確認_送信ファイル_項目分割!I$4)) | J9: =IF(請求確認_送信ファイル!$D6="","",MIDB(請求確認_送信ファイル!$D6,請求確認_送信ファイル_項目分割!J$3,請求確認_送信ファイル_項目分割!J$4)) | K9: =IF(請求確認_送信ファイル!$D6="","",MIDB(請求確認_送信ファイル!$D6,請求確認_送信ファイル_項目分割!K$3,請求確認_送信ファイル_項目分割!K$4)) | ... EB9: =IF(請求確認_送信ファイル!$D6="","",MIDB(請求確認_送信ファイル!$D6,請求確認_送信ファイル_項目分割!EB$3,請求確認_送信ファイル_項目分割!EB$4))
B10: =ROW()-6 -> 4 | C10: =IF(請求確認_送信ファイル!C7="","",請求確認_送信ファイル!C7) -> No34,35,39 | D10: =IF(請求確認_送信ファイル!$D7="","",MIDB(請求確認_送信ファイル!$D7,請求確認_送信ファイル_項目分割!D$3,請求確認_送信ファイル_項目分割!D$4)) | E10: =IF(請求確認_送信ファイル!$D7="","",MIDB(請求確認_送信ファイル!$D7,請求確認_送信ファイル_項目分割!E$3,請求確認_送信ファイル_項目分割!E$4)) | F10: =IF(請求確認_送信ファイル!$D7="","",MIDB(請求確認_送信ファイル!$D7,請求確認_送信ファイル_項目分割!F$3,請求確認_送信ファイル_項目分割!F$4)) | G10: =IF(請求確認_送信ファイル!$D7="","",MIDB(請求確認_送信ファイル!$D7,請求確認_送信ファイル_項目分割!G$3,請求確認_送信ファイル_項目分割!G$4)) | H10: =IF(請求確認_送信ファイル!$D7="","",MIDB(請求確認_送信ファイル!$D7,請求確認_送信ファイル_項目分割!H$3,請求確認_送信ファイル_項目分割!H$4)) | I10: =IF(請求確認_送信ファイル!$D7="","",MIDB(請求確認_送信ファイル!$D7,請求確認_送信ファイル_項目分割!I$3,請求確認_送信ファイル_項目分割!I$4)) | J10: =IF(請求確認_送信ファイル!$D7="","",MIDB(請求確認_送信ファイル!$D7,請求確認_送信ファイル_項目分割!J$3,請求確認_送信ファイル_項目分割!J$4)) | K10: =IF(請求確認_送信ファイル!$D7="","",MIDB(請求確認_送信ファイル!$D7,請求確認_送信ファイル_項目分割!K$3,請求確認_送信ファイル_項目分割!K$4)) | ... EB10: =IF(請求確認_送信ファイル!$D7="","",MIDB(請求確認_送信ファイル!$D7,請求確認_送信ファイル_項目分割!EB$3,請求確認_送信ファイル_項目分割!EB$4))
B11: =ROW()-6 -> 5 | C11: =IF(請求確認_送信ファイル!C8="","",請求確認_送信ファイル!C8) -> No34,35,39 | D11: =IF(請求確認_送信ファイル!$D8="","",MIDB(請求確認_送信ファイル!$D8,請求確認_送信ファイル_項目分割!D$3,請求確認_送信ファイル_項目分割!D$4)) | E11: =IF(請求確認_送信ファイル!$D8="","",MIDB(請求確認_送信ファイル!$D8,請求確認_送信ファイル_項目分割!E$3,請求確認_送信ファイル_項目分割!E$4)) | F11: =IF(請求確認_送信ファイル!$D8="","",MIDB(請求確認_送信ファイル!$D8,請求確認_送信ファイル_項目分割!F$3,請求確認_送信ファイル_項目分割!F$4)) | G11: =IF(請求確認_送信ファイル!$D8="","",MIDB(請求確認_送信ファイル!$D8,請求確認_送信ファイル_項目分割!G$3,請求確認_送信ファイル_項目分割!G$4)) | H11: =IF(請求確認_送信ファイル!$D8="","",MIDB(請求確認_送信ファイル!$D8,請求確認_送信ファイル_項目分割!H$3,請求確認_送信ファイル_項目分割!H$4)) | I11: =IF(請求確認_送信ファイル!$D8="","",MIDB(請求確認_送信ファイル!$D8,請求確認_送信ファイル_項目分割!I$3,請求確認_送信ファイル_項目分割!I$4)) | J11: =IF(請求確認_送信ファイル!$D8="","",MIDB(請求確認_送信ファイル!$D8,請求確認_送信ファイル_項目分割!J$3,請求確認_送信ファイル_項目分割!J$4)) | K11: =IF(請求確認_送信ファイル!$D8="","",MIDB(請求確認_送信ファイル!$D8,請求確認_送信ファイル_項目分割!K$3,請求確認_送信ファイル_項目分割!K$4)) | ... EB11: =IF(請求確認_送信ファイル!$D8="","",MIDB(請求確認_送信ファイル!$D8,請求確認_送信ファイル_項目分割!EB$3,請求確認_送信ファイル_項目分割!EB$4))
B12: =ROW()-6 -> 6 | C12: =IF(請求確認_送信ファイル!C9="","",請求確認_送信ファイル!C9) -> No34,35,39 | D12: =IF(請求確認_送信ファイル!$D9="","",MIDB(請求確認_送信ファイル!$D9,請求確認_送信ファイル_項目分割!D$3,請求確認_送信ファイル_項目分割!D$4)) | E12: =IF(請求確認_送信ファイル!$D9="","",MIDB(請求確認_送信ファイル!$D9,請求確認_送信ファイル_項目分割!E$3,請求確認_送信ファイル_項目分割!E$4)) | F12: =IF(請求確認_送信ファイル!$D9="","",MIDB(請求確認_送信ファイル!$D9,請求確認_送信ファイル_項目分割!F$3,請求確認_送信ファイル_項目分割!F$4)) | G12: =IF(請求確認_送信ファイル!$D9="","",MIDB(請求確認_送信ファイル!$D9,請求確認_送信ファイル_項目分割!G$3,請求確認_送信ファイル_項目分割!G$4)) | H12: =IF(請求確認_送信ファイル!$D9="","",MIDB(請求確認_送信ファイル!$D9,請求確認_送信ファイル_項目分割!H$3,請求確認_送信ファイル_項目分割!H$4)) | I12: =IF(請求確認_送信ファイル!$D9="","",MIDB(請求確認_送信ファイル!$D9,請求確認_送信ファイル_項目分割!I$3,請求確認_送信ファイル_項目分割!I$4)) | J12: =IF(請求確認_送信ファイル!$D9="","",MIDB(請求確認_送信ファイル!$D9,請求確認_送信ファイル_項目分割!J$3,請求確認_送信ファイル_項目分割!J$4)) | K12: =IF(請求確認_送信ファイル!$D9="","",MIDB(請求確認_送信ファイル!$D9,請求確認_送信ファイル_項目分割!K$3,請求確認_送信ファイル_項目分割!K$4)) | ... EB12: =IF(請求確認_送信ファイル!$D9="","",MIDB(請求確認_送信ファイル!$D9,請求確認_送信ファイル_項目分割!EB$3,請求確認_送信ファイル_項目分割!EB$4))
B13: =ROW()-6 -> 7 | C13: =IF(請求確認_送信ファイル!C10="","",請求確認_送信ファイル!C10) | D13: =IF(請求確認_送信ファイル!$D10="","",MIDB(請求確認_送信ファイル!$D10,請求確認_送信ファイル_項目分割!D$3,請求確認_送信ファイル_項目分割!D$4)) | E13: =IF(請求確認_送信ファイル!$D10="","",MIDB(請求確認_送信ファイル!$D10,請求確認_送信ファイル_項目分割!E$3,請求確認_送信ファイル_項目分割!E$4)) | F13: =IF(請求確認_送信ファイル!$D10="","",MIDB(請求確認_送信ファイル!$D10,請求確認_送信ファイル_項目分割!F$3,請求確認_送信ファイル_項目分割!F$4)) | G13: =IF(請求確認_送信ファイル!$D10="","",MIDB(請求確認_送信ファイル!$D10,請求確認_送信ファイル_項目分割!G$3,請求確認_送信ファイル_項目分割!G$4)) | H13: =IF(請求確認_送信ファイル!$D10="","",MIDB(請求確認_送信ファイル!$D10,請求確認_送信ファイル_項目分割!H$3,請求確認_送信ファイル_項目分割!H$4)) | I13: =IF(請求確認_送信ファイル!$D10="","",MIDB(請求確認_送信ファイル!$D10,請求確認_送信ファイル_項目分割!I$3,請求確認_送信ファイル_項目分割!I$4)) | J13: =IF(請求確認_送信ファイル!$D10="","",MIDB(請求確認_送信ファイル!$D10,請求確認_送信ファイル_項目分割!J$3,請求確認_送信ファイル_項目分割!J$4)) | K13: =IF(請求確認_送信ファイル!$D10="","",MIDB(請求確認_送信ファイル!$D10,請求確認_送信ファイル_項目分割!K$3,請求確認_送信ファイル_項目分割!K$4)) | ... EB13: =IF(請求確認_送信ファイル!$D10="","",MIDB(請求確認_送信ファイル!$D10,請求確認_送信ファイル_項目分割!EB$3,請求確認_送信ファイル_項目分割!EB$4))
B14: =ROW()-6 -> 8 | C14: =IF(請求確認_送信ファイル!C11="","",請求確認_送信ファイル!C11) | D14: =IF(請求確認_送信ファイル!$D11="","",MIDB(請求確認_送信ファイル!$D11,請求確認_送信ファイル_項目分割!D$3,請求確認_送信ファイル_項目分割!D$4)) | E14: =IF(請求確認_送信ファイル!$D11="","",MIDB(請求確認_送信ファイル!$D11,請求確認_送信ファイル_項目分割!E$3,請求確認_送信ファイル_項目分割!E$4)) | F14: =IF(請求確認_送信ファイル!$D11="","",MIDB(請求確認_送信ファイル!$D11,請求確認_送信ファイル_項目分割!F$3,請求確認_送信ファイル_項目分割!F$4)) | G14: =IF(請求確認_送信ファイル!$D11="","",MIDB(請求確認_送信ファイル!$D11,請求確認_送信ファイル_項目分割!G$3,請求確認_送信ファイル_項目分割!G$4)) | H14: =IF(請求確認_送信ファイル!$D11="","",MIDB(請求確認_送信ファイル!$D11,請求確認_送信ファイル_項目分割!H$3,請求確認_送信ファイル_項目分割!H$4)) | I14: =IF(請求確認_送信ファイル!$D11="","",MIDB(請求確認_送信ファイル!$D11,請求確認_送信ファイル_項目分割!I$3,請求確認_送信ファイル_項目分割!I$4)) | J14: =IF(請求確認_送信ファイル!$D11="","",MIDB(請求確認_送信ファイル!$D11,請求確認_送信ファイル_項目分割!J$3,請求確認_送信ファイル_項目分割!J$4)) | K14: =IF(請求確認_送信ファイル!$D11="","",MIDB(請求確認_送信ファイル!$D11,請求確認_送信ファイル_項目分割!K$3,請求確認_送信ファイル_項目分割!K$4)) | ... EB14: =IF(請求確認_送信ファイル!$D11="","",MIDB(請求確認_送信ファイル!$D11,請求確認_送信ファイル_項目分割!EB$3,請求確認_送信ファイル_項目分割!EB$4))
B15: =ROW()-6 -> 9 | C15: =IF(請求確認_送信ファイル!C12="","",請求確認_送信ファイル!C12) | D15: =IF(請求確認_送信ファイル!$D12="","",MIDB(請求確認_送信ファイル!$D12,請求確認_送信ファイル_項目分割!D$3,請求確認_送信ファイル_項目分割!D$4)) | E15: =IF(請求確認_送信ファイル!$D12="","",MIDB(請求確認_送信ファイル!$D12,請求確認_送信ファイル_項目分割!E$3,請求確認_送信ファイル_項目分割!E$4)) | F15: =IF(請求確認_送信ファイル!$D12="","",MIDB(請求確認_送信ファイル!$D12,請求確認_送信ファイル_項目分割!F$3,請求確認_送信ファイル_項目分割!F$4)) | G15: =IF(請求確認_送信ファイル!$D12="","",MIDB(請求確認_送信ファイル!$D12,請求確認_送信ファイル_項目分割!G$3,請求確認_送信ファイル_項目分割!G$4)) | H15: =IF(請求確認_送信ファイル!$D12="","",MIDB(請求確認_送信ファイル!$D12,請求確認_送信ファイル_項目分割!H$3,請求確認_送信ファイル_項目分割!H$4)) | I15: =IF(請求確認_送信ファイル!$D12="","",MIDB(請求確認_送信ファイル!$D12,請求確認_送信ファイル_項目分割!I$3,請求確認_送信ファイル_項目分割!I$4)) | J15: =IF(請求確認_送信ファイル!$D12="","",MIDB(請求確認_送信ファイル!$D12,請求確認_送信ファイル_項目分割!J$3,請求確認_送信ファイル_項目分割!J$4)) | K15: =IF(請求確認_送信ファイル!$D12="","",MIDB(請求確認_送信ファイル!$D12,請求確認_送信ファイル_項目分割!K$3,請求確認_送信ファイル_項目分割!K$4)) | ... EB15: =IF(請求確認_送信ファイル!$D12="","",MIDB(請求確認_送信ファイル!$D12,請求確認_送信ファイル_項目分割!EB$3,請求確認_送信ファイル_項目分割!EB$4))
B16: =ROW()-6 -> 10 | C16: =IF(請求確認_送信ファイル!C13="","",請求確認_送信ファイル!C13) | D16: =IF(請求確認_送信ファイル!$D13="","",MIDB(請求確認_送信ファイル!$D13,請求確認_送信ファイル_項目分割!D$3,請求確認_送信ファイル_項目分割!D$4)) | E16: =IF(請求確認_送信ファイル!$D13="","",MIDB(請求確認_送信ファイル!$D13,請求確認_送信ファイル_項目分割!E$3,請求確認_送信ファイル_項目分割!E$4)) | F16: =IF(請求確認_送信ファイル!$D13="","",MIDB(請求確認_送信ファイル!$D13,請求確認_送信ファイル_項目分割!F$3,請求確認_送信ファイル_項目分割!F$4)) | G16: =IF(請求確認_送信ファイル!$D13="","",MIDB(請求確認_送信ファイル!$D13,請求確認_送信ファイル_項目分割!G$3,請求確認_送信ファイル_項目分割!G$4)) | H16: =IF(請求確認_送信ファイル!$D13="","",MIDB(請求確認_送信ファイル!$D13,請求確認_送信ファイル_項目分割!H$3,請求確認_送信ファイル_項目分割!H$4)) | I16: =IF(請求確認_送信ファイル!$D13="","",MIDB(請求確認_送信ファイル!$D13,請求確認_送信ファイル_項目分割!I$3,請求確認_送信ファイル_項目分割!I$4)) | J16: =IF(請求確認_送信ファイル!$D13="","",MIDB(請求確認_送信ファイル!$D13,請求確認_送信ファイル_項目分割!J$3,請求確認_送信ファイル_項目分割!J$4)) | K16: =IF(請求確認_送信ファイル!$D13="","",MIDB(請求確認_送信ファイル!$D13,請求確認_送信ファイル_項目分割!K$3,請求確認_送信ファイル_項目分割!K$4)) | ... EB16: =IF(請求確認_送信ファイル!$D13="","",MIDB(請求確認_送信ファイル!$D13,請求確認_送信ファイル_項目分割!EB$3,請求確認_送信ファイル_項目分割!EB$4))
B17: =ROW()-6 -> 11 | C17: =IF(請求確認_送信ファイル!C14="","",請求確認_送信ファイル!C14) | D17: =IF(請求確認_送信ファイル!$D14="","",MIDB(請求確認_送信ファイル!$D14,請求確認_送信ファイル_項目分割!D$3,請求確認_送信ファイル_項目分割!D$4)) | E17: =IF(請求確認_送信ファイル!$D14="","",MIDB(請求確認_送信ファイル!$D14,請求確認_送信ファイル_項目分割!E$3,請求確認_送信ファイル_項目分割!E$4)) | F17: =IF(請求確認_送信ファイル!$D14="","",MIDB(請求確認_送信ファイル!$D14,請求確認_送信ファイル_項目分割!F$3,請求確認_送信ファイル_項目分割!F$4)) | G17: =IF(請求確認_送信ファイル!$D14="","",MIDB(請求確認_送信ファイル!$D14,請求確認_送信ファイル_項目分割!G$3,請求確認_送信ファイル_項目分割!G$4)) | H17: =IF(請求確認_送信ファイル!$D14="","",MIDB(請求確認_送信ファイル!$D14,請求確認_送信ファイル_項目分割!H$3,請求確認_送信ファイル_項目分割!H$4)) | I17: =IF(請求確認_送信ファイル!$D14="","",MIDB(請求確認_送信ファイル!$D14,請求確認_送信ファイル_項目分割!I$3,請求確認_送信ファイル_項目分割!I$4)) | J17: =IF(請求確認_送信ファイル!$D14="","",MIDB(請求確認_送信ファイル!$D14,請求確認_送信ファイル_項目分割!J$3,請求確認_送信ファイル_項目分割!J$4)) | K17: =IF(請求確認_送信ファイル!$D14="","",MIDB(請求確認_送信ファイル!$D14,請求確認_送信ファイル_項目分割!K$3,請求確認_送信ファイル_項目分割!K$4)) | ... EB17: =IF(請求確認_送信ファイル!$D14="","",MIDB(請求確認_送信ファイル!$D14,請求確認_送信ファイル_項目分割!EB$3,請求確認_送信ファイル_項目分割!EB$4))
B18: =ROW()-6 -> 12 | C18: =IF(請求確認_送信ファイル!C15="","",請求確認_送信ファイル!C15) | D18: =IF(請求確認_送信ファイル!$D15="","",MIDB(請求確認_送信ファイル!$D15,請求確認_送信ファイル_項目分割!D$3,請求確認_送信ファイル_項目分割!D$4)) | E18: =IF(請求確認_送信ファイル!$D15="","",MIDB(請求確認_送信ファイル!$D15,請求確認_送信ファイル_項目分割!E$3,請求確認_送信ファイル_項目分割!E$4)) | F18: =IF(請求確認_送信ファイル!$D15="","",MIDB(請求確認_送信ファイル!$D15,請求確認_送信ファイル_項目分割!F$3,請求確認_送信ファイル_項目分割!F$4)) | G18: =IF(請求確認_送信ファイル!$D15="","",MIDB(請求確認_送信ファイル!$D15,請求確認_送信ファイル_項目分割!G$3,請求確認_送信ファイル_項目分割!G$4)) | H18: =IF(請求確認_送信ファイル!$D15="","",MIDB(請求確認_送信ファイル!$D15,請求確認_送信ファイル_項目分割!H$3,請求確認_送信ファイル_項目分割!H$4)) | I18: =IF(請求確認_送信ファイル!$D15="","",MIDB(請求確認_送信ファイル!$D15,請求確認_送信ファイル_項目分割!I$3,請求確認_送信ファイル_項目分割!I$4)) | J18: =IF(請求確認_送信ファイル!$D15="","",MIDB(請求確認_送信ファイル!$D15,請求確認_送信ファイル_項目分割!J$3,請求確認_送信ファイル_項目分割!J$4)) | K18: =IF(請求確認_送信ファイル!$D15="","",MIDB(請求確認_送信ファイル!$D15,請求確認_送信ファイル_項目分割!K$3,請求確認_送信ファイル_項目分割!K$4)) | ... EB18: =IF(請求確認_送信ファイル!$D15="","",MIDB(請求確認_送信ファイル!$D15,請求確認_送信ファイル_項目分割!EB$3,請求確認_送信ファイル_項目分割!EB$4))
B19: =ROW()-6 -> 13 | C19: =IF(請求確認_送信ファイル!C16="","",請求確認_送信ファイル!C16) | D19: =IF(請求確認_送信ファイル!$D16="","",MIDB(請求確認_送信ファイル!$D16,請求確認_送信ファイル_項目分割!D$3,請求確認_送信ファイル_項目分割!D$4)) | E19: =IF(請求確認_送信ファイル!$D16="","",MIDB(請求確認_送信ファイル!$D16,請求確認_送信ファイル_項目分割!E$3,請求確認_送信ファイル_項目分割!E$4)) | F19: =IF(請求確認_送信ファイル!$D16="","",MIDB(請求確認_送信ファイル!$D16,請求確認_送信ファイル_項目分割!F$3,請求確認_送信ファイル_項目分割!F$4)) | G19: =IF(請求確認_送信ファイル!$D16="","",MIDB(請求確認_送信ファイル!$D16,請求確認_送信ファイル_項目分割!G$3,請求確認_送信ファイル_項目分割!G$4)) | H19: =IF(請求確認_送信ファイル!$D16="","",MIDB(請求確認_送信ファイル!$D16,請求確認_送信ファイル_項目分割!H$3,請求確認_送信ファイル_項目分割!H$4)) | I19: =IF(請求確認_送信ファイル!$D16="","",MIDB(請求確認_送信ファイル!$D16,請求確認_送信ファイル_項目分割!I$3,請求確認_送信ファイル_項目分割!I$4)) | J19: =IF(請求確認_送信ファイル!$D16="","",MIDB(請求確認_送信ファイル!$D16,請求確認_送信ファイル_項目分割!J$3,請求確認_送信ファイル_項目分割!J$4)) | K19: =IF(請求確認_送信ファイル!$D16="","",MIDB(請求確認_送信ファイル!$D16,請求確認_送信ファイル_項目分割!K$3,請求確認_送信ファイル_項目分割!K$4)) | ... EB19: =IF(請求確認_送信ファイル!$D16="","",MIDB(請求確認_送信ファイル!$D16,請求確認_送信ファイル_項目分割!EB$3,請求確認_送信ファイル_項目分割!EB$4))
... B49: =ROW()-6 -> 43 | C49: =IF(請求確認_送信ファイル!C46="","",請求確認_送信ファイル!C46) | D49: =IF(請求確認_送信ファイル!$D46="","",MIDB(請求確認_送信ファイル!$D46,請求確認_送信ファイル_項目分割!D$3,請求確認_送信ファイル_項目分割!D$4)) | E49: =IF(請求確認_送信ファイル!$D46="","",MIDB(請求確認_送信ファイル!$D46,請求確認_送信ファイル_項目分割!E$3,請求確認_送信ファイル_項目分割!E$4)) | F49: =IF(請求確認_送信ファイル!$D46="","",MIDB(請求確認_送信ファイル!$D46,請求確認_送信ファイル_項目分割!F$3,請求確認_送信ファイル_項目分割!F$4)) | G49: =IF(請求確認_送信ファイル!$D46="","",MIDB(請求確認_送信ファイル!$D46,請求確認_送信ファイル_項目分割!G$3,請求確認_送信ファイル_項目分割!G$4)) | H49: =IF(請求確認_送信ファイル!$D46="","",MIDB(請求確認_送信ファイル!$D46,請求確認_送信ファイル_項目分割!H$3,請求確認_送信ファイル_項目分割!H$4)) | I49: =IF(請求確認_送信ファイル!$D46="","",MIDB(請求確認_送信ファイル!$D46,請求確認_送信ファイル_項目分割!I$3,請求確認_送信ファイル_項目分割!I$4)) | J49: =IF(請求確認_送信ファイル!$D46="","",MIDB(請求確認_送信ファイル!$D46,請求確認_送信ファイル_項目分割!J$3,請求確認_送信ファイル_項目分割!J$4)) | K49: =IF(請求確認_送信ファイル!$D46="","",MIDB(請求確認_送信ファイル!$D46,請求確認_送信ファイル_項目分割!K$3,請求確認_送信ファイル_項目分割!K$4)) | ... EB49: =IF(請求確認_送信ファイル!$D46="","",MIDB(請求確認_送信ファイル!$D46,請求確認_送信ファイル_項目分割!EB$3,請求確認_送信ファイル_項目分割!EB$4))

Sheet ７．項目転送 (請求データ送信ファイル)
A6: ■ | B6: 請求確認データ送信ファイルマッピング仕様 | D6: ［ ］：６．１．相手先別データレイアウト | E6: △：半角空白、□：全角空白
A7: 請求確認データ送信ファイルマッピング | D7: 設 定 値
A8: № | B8: 項 目 名（和名） | C8: 項 目 名（英名） | D8: 単 純 転 送 | E8: 編 集 内 容
A9: =ROW()-8 -> 1 | B9: リザーブ | C9: RESERVE | E9: "△"
A10: =ROW()-8 -> 2 | B10: BPID | C10: BPID | E10: "JPCA0102"
A11: =ROW()-8 -> 3 | B11: 送受信 | C11: SND_RCV | E11: "S"
A12: =ROW()-8 -> 4 | B12: 情報区分 | C12: INF_KBN | E12: "1720"
A13: =ROW()-8 -> 5 | B13: 自社コード | C13: JISHA_CD | E13: "101913000010"
A14: =ROW()-8 -> 6 | B14: 相手先コード | C14: AITE_SAKI_CD | E14: "506040999995"
A15: =ROW()-8 -> 7 | B15: データ種別 | C15: DATA_SBT | E15: "1720"
A16: =ROW()-8 -> 8 | B16: 処理区分 | C16: FUNC_KBN | D16: [処理区分]
A17: =ROW()-8 -> 9 | B17: 処理年月日 | C17: FUNC_YMD | E17: yymmdd(システム日付）
A18: =ROW()-8 -> 10 | B18: 処理時刻 | C18: FUNC_TM | E18: HHMMMSS(システム時刻)
A19: =ROW()-8 -> 11 | B19: 赤黒区分 | C19: AKAKURO_KBN | D19: [赤黒区分]
A20: =ROW()-8 -> 12 | B20: 発注者企業コード | C20: HACSHA_KIGYO_CD | D20: [発注者企業コード]
A21: =ROW()-8 -> 13 | B21: 発注者部門コード | C21: HACSHA_BMN_CD | D21: [発注者部門コード]
A22: =ROW()-8 -> 14 | B22: 受注者企業コード | C22: JUC_KIGYO_CD | D22: [受注者企業コード]
A23: =ROW()-8 -> 15 | B23: 受注者部門コード | C23: JUC_BMN_CD | D23: [受注者部門コード]
A24: =ROW()-8 -> 16 | B24: 請求者企業コード | C24: SEIKYU_KIGYO_CD | D24: [請求者企業コード]
A25: =ROW()-8 -> 17 | B25: 請求者部門コード | C25: SEIKYU_BMN_CD | D25: [請求者部門コード]
A26: =ROW()-8 -> 18 | B26: 支払者企業コード | C26: PAY_KIGYO_CD | D26: [支払者企業コード]
A27: =ROW()-8 -> 19 | B27: 支払先部門コード | C27: PAY_BMN_CD | D27: [支払者部門コード]
A28: =ROW()-8 -> 20 | B28: 契約番号 | C28: KEIYAKU_NO | D28: [契約番号]
A29: =ROW()-8 -> 21 | B29: 注文番号 | C29: CHUMON_NO | D29: [注文番号]
A30: =ROW()-8 -> 22 | B30: 受注番号 | C30: JUC_NO | D30: [受注番号]
... A52: =ROW()-8 -> 44 | B52: 金額算出数量 | C52: GAKU_CLC_SURYO | D52: [金額算出数量]
A53: =ROW()-8 -> 45 | B53: 荷姿 | C53: NISUGATA | E53: 結合文字（[荷姿ｺｰﾄﾞ]、[荷姿名]）
A54: =ROW()-8 -> 46 | B54: 容量 | C54: YORYO | D54: [容量]
A55: =ROW()-8 -> 47 | B55: 販売金額 | C55: HAN_GAKU | D55: [販売金額]
A56: =ROW()-8 -> 48 | B56: 消費税額 | C56: SHOHIZEI_GAKU | D56: [消費税額]
A57: =ROW()-8 -> 49 | B57: 税込請求額 | C57: ZEIKOMI_SEIKYU_GAKU | D57: [税込請求額]
A58: =ROW()-8 -> 50 | B58: 単価金額区分 | C58: TANK_GAKU_KBN | D58: [単価･金額区分]
A59: =ROW()-8 -> 51 | B59: 取引区分 | C59: TORIHIKI_KBN | D59: [取引区分]
A60: =ROW()-8 -> 52 | B60: 遡及区分 | C60: SOKYU_KBN | D60: [遡及区分]
A61: =ROW()-8 -> 53 | B61: 出荷請求区分 | C61: SHUKKA_SEIKYU_KBN | D61: [出荷請求区分]
A62: =ROW()-8 -> 54 | B62: 課税区分 | C62: KAZEI_KBN | D62: [課税区分]
A63: =ROW()-8 -> 55 | B63: バックオーダー区分 | C63: BACK_ORDER_KBN | D63: [バックオーダー区分]
A64: =ROW()-8 -> 56 | B64: 出荷年月日（予定） | C64: SHUKKA_YMD_YOTEI | D64: [出荷請求年月日(予定)]
A65: =ROW()-8 -> 57 | B65: 出荷報告番号 | C65: SHUKKA_HOKOKU_NO | D65: [出荷報告番号]
... A70: =ROW()-8 -> 62 | B70: 国内輸出区分 | C70: DOM_EXP_KBN | D70: [国内輸出区分]
...

Sheet Workspace
