Workbook
Name _1枚目: #REF!
Name _2枚目: #REF!
Name _3枚目: #REF!
Name _4枚目: #REF!
Name a: #REF!
Name AA: #REF!
Name b: #REF!
Name B_下: #REF!
Name B_上: #REF!
Name CSV項目編集仕様: #REF!
Name dd: #REF!
Name DS_下: #REF!
Name DS_上: #REF!
Name ＤＳ担当: #REF!
Name GUI名称: #REF!
Name ＩＤ: #REF!
Name IO: #REF!
Name IT項目: #REF!
Name kkk: #REF!
Name NULL: #REF!
Name ON: #REF!
Name PCL_下: #REF!
Name PCL_上: #REF!
Name ＰＧ担当: #REF!
Name PT項目: #REF!
Name RI: #REF!
Name riyu: #REF!
Name RYZ: #REF!
Name STEP_下: #REF!
Name STEP_上: #REF!
Name UD: #REF!
Name x: [0]!x
Name カーソルキー移動↑↓←: #REF!
Name カテゴリ一覧: #REF!
Name クラス名: #REF!
Name サブシステム名: #REF!
Name システム名: #REF!
Name セパレータ: #REF!
Name タイトル: #REF!
Name チェック: #REF!
Name チェック実行アプリ: #REF!
Name ﾃｰﾌﾞﾙID群: #REF!
Name ファイル名: #REF!
Name ファンクションキー割当: #REF!
Name ブロック: #REF!
Name ブロックＩＤ: #REF!
Name レベル: #REF!
Name 移行元ﾌｧｲﾙＩＤ: #REF!
Name 移行元項目ＩＤ: #REF!
Name 一意: #REF!
Name 一覧２: #REF!
Name 可変行表示: #REF!
Name 確認区分: #REF!
Name 管理No: #REF!
Name 基準稼働時間: #REF!
Name 期限: #REF!
Name 機能名_選択: #REF!
Name 共通: #REF!
Name 業: #REF!
Name 業務間連携: #REF!

Sheet 表紙
C2: 稲畑産業株式会社様
A8: EDIシステム
A10: バッチ処理設計書
A13: 共通処理_EDI送信_支払_データ抽出
A17: - Ver.2.00 -
A22: 45811
A24: 富士通株式会社
V28: 承認 | AA28: 作成
AA29: 45811
AA30: FJ)松田

Sheet 変更履歴
A1: 稲畑産業 株式会社 | F1: バッチ処理設計書 | T1: 取引先名 | AH1: 取引先略称ID | AS1: カテゴリ名 | BB1: 作成者 | BF1: 作成日 | BJ1: 更新者 | BN1: 更新日
T3: - | AH3: - | AS3: 支払・支払明細 | BB3: FJ)松田 | BF3: 45811
B7: № | D7: バージョン | H7: 変更日付 | L7: 変更者 | O7: 区分 | Q7: 変更管理番号 | U7: 変更箇所 | AF7: 変更内容 | AY7: 備考
B8: =ROW()-7 -> 1 | D8: 2.00 | H8: 45811 | L8: FJ松田 | O8: 新規 | Q8: R60795 | AF8: 新規作成 | AY8: EDIミドル移行対応
B9: =ROW()-7 -> 2
B10: =ROW()-7 -> 3
B11: =ROW()-7 -> 4
B12: =ROW()-7 -> 5
B13: =ROW()-7 -> 6
B14: =ROW()-7 -> 7
B15: =ROW()-7 -> 8
B16: =ROW()-7 -> 9
B17: =ROW()-7 -> 10
B18: =ROW()-7 -> 11
B19: =ROW()-7 -> 12
B20: =ROW()-7 -> 13
... B52: =ROW()-7 -> 45

Sheet １．機能
A1: 稲畑産業 株式会社 | E1: バッチ処理設計書 | O1: 取引先名 | X1: 取引先略称ID | AC1: カテゴリ名 | AG1: 作成者 | AJ1: 作成日 | AM1: 更新者 | AP1: 更新日
O3: =変更履歴!T3 -> - | X3: =変更履歴!AH3 -> - | AC3: =変更履歴!AS3 -> 支払・支払明細 | AG3: =変更履歴!BB3 -> FJ)松田 | AJ3: =変更履歴!BF3 -> 45811
B6: ①目的
C8: ・EDI送信DB_支払より対象のデータを抽出し、EDI受信DB_仕入先と結合して、EDI採番マスタの連番を設定する。
C9: ・後続の処理に必要な各取引先向けの連携ファイルを作成する。
B11: ②機能概要
C13: ・EDI送信DB_支払より、支払データを抽出し、処理対象件数を確認する。
C14: ・処理対象件数が1件以上の場合、共通処理 mplt_CMN_EDI送信DB_支払更新１ により送信状況種別を「1（処理中）」に更新する。
C15: ・mplt_CMN_EDI採番マスタ連番取得更新を呼び出し、EDI採番マスタのEDI連番を取得・更新する。
C16: ・支払データとEDI受信DB_仕入先を受信SEQ番号で結合し、結合データを作成する。
C17: ・結合データに、取得したEDI連番を設定し、連携ファイルとする。
B19: ③入出力情報
C21: [入力]
C22: テーブル名orファイル名 | M22: 抽出条件 | AE22: 使用目的
C23: EDI送信DB_支払 | M23: データ交換ID = (パラメータ)データ交換ID かつ | AE23: 処理対象レコードの抽出
M24: EDI_機能カテゴリコード = A140 かつ EDI_送信状況種別 = 0
C25: EDI採番マスタ | M25: EDI採番種別 = '01' かつ EDI採番取得キー = 'ZZZZZZZZZZ' | AE25: 連番の取得
C27: EDI受信DB_仕入先 | M27: EDI受信DB_仕入先.データ交換ID = (パラメータ)データ交換ID かつ | AE27: 連携ファイル作成
M28: EDI受信DB_仕入先.受信SEQ番号=支払データ.受信SEQ番号
C32: [出力]
C33: テーブル名orファイル名 | M33: 更新条件 | AE33: 使用目的
C34: EDI送信DB_支払 | M34: 対象レコードのEDI送信状況種別を "1"（処理中）に更新 | AE34: 処理中フラグを設定
M35: ※(キー) 送信シーケンスNo
C36: EDI採番マスタ | M36: 取得したEDI連番を +1 してUPDATE | AE36: 次回送信用の連番更新
C38: 連携ファイル | M38: 採番済み連番＋対象レコード | AE38: 個別処理への中間ファイルとして出力
M39: 対象レコードに取得済のEDI連番を設定 | AE39: 処理受付番号の付与
B46: ④機能詳細
C48: (1) 対象データの抽出
D50: EDI送信DB_支払テーブルより、以下の条件で処理対象のデータを抽出し、件数を取得する。
D52: 抽出条件：
E53: ・データ交換ID = （パラメータ）データ交換ID
E54: ・EDI_機能カテゴリコード = "A140"
E55: ・EDI_送信状況種別 = "0"（未処理）
D56: ※件数が 0 件の場合は、リターンコード「10」を設定し、処理を異常終了する。
D58: ファイルに抽出した件数を出力する。
E59: 配置箇所：EDIサーバ\PRD\Temp\
E60: ファイル名:$取引先ID$A140S01001
C62: (2) EDI送信DB_支払のステータス更新（共通処理呼び出し）
D64: (1)で抽出したデータに対して、mplt_CMN_EDI送信DB_支払更新１を呼び出し、以下の処理を行う。
E66: ①EDI送信DB_支払より対象のﾃﾞｰﾀをSELECT for Updateでレコードロックする
...

Sheet ２．項目転送（EDI送信DB_支払）_更新
A6: ■ | B6: EDI送信DB_支払 更新
A7: EDI送信DB_支払マッピング | H7: 設 定 値
A8: № | B8: 項目グループ | C8: 項 目 名（和名） | D8: 項 目 名（英名） | E8: 型 | F8: 桁数 | G8: 小数桁数 | H8: 単 純 転 送 | I8: 編 集 内 容
A9: =ROW()-8 -> 1 | C9: 送信シーケンスNO | D9: SND_SEQ_NO | E9: 半角英数字 | F9: 10
A10: =ROW()-8 -> 2 | C10: データ交換ID | D10: DATA_KOKAN_ID | E10: 半角英数字 | F10: 6
A11: =ROW()-8 -> 3 | C11: EDI_機能カテゴリコード | D11: EDI_KINO_CATEGORY_CD | E11: 半角英数字 | F11: 4
A12: =ROW()-8 -> 4 | C12: 仕入先コード | D12: SUP_CD | E12: 半角数字 | F12: 10
A13: =ROW()-8 -> 5 | C13: 販区 | D13: HAN_KBN | E13: 半角英数字 | F13: 3
A14: =ROW()-8 -> 6 | C14: 起算日 | D14: KISAN_D | E14: 半角英数字 | F14: 8
A15: =ROW()-8 -> 7 | C15: 金種 | D15: KINSHU | E15: 半角英字 | F15: 1
A16: =ROW()-8 -> 8 | C16: 本支店コード | D16: HONSHITEN_CD | E16: 半角数字 | F16: 1
A17: =ROW()-8 -> 9 | C17: 締切年月日 | D17: SHIMEKIRI_YMD | E17: 日付(年月日) | F17: 8
A18: =ROW()-8 -> 10 | C18: 満期日 | D18: MANKI_D | E18: 半角英数字 | F18: 8
A19: =ROW()-8 -> 11 | C19: 銀行コード | D19: BANK_CD | E19: 半角数字 | F19: 4
A20: =ROW()-8 -> 12 | C20: 支店コード | D20: SHITEN_CD | E20: 半角数字 | F20: 3
... A24: =ROW()-8 -> 16 | C24: 振込先口座NO | D24: FURIKOMI_KOZA_NO | E24: 半角英数字 | F24: 7
A25: =ROW()-8 -> 17 | C25: EDI_今回支払金額 | D25: EDI_KONKAI_PAY_GAKU | E25: 小数付き数値 | F25: 13 | G25: 0
A26: =ROW()-8 -> 18 | C26: 支払年月日 | D26: PAY_YMD | E26: 日付(年月日) | F26: 8
A27: =ROW()-8 -> 19 | C27: EDI_送信状況種別 | D27: EDI_SND_JOKYO_SBT | E27: 半角英数字 | F27: 1 | I27: EDI送信状況種別="1"（処理中）に設定
A28: =ROW()-8 -> 20 | C28: 送信日時 | D28: SND_DT | E28: 全半角混在文字 | F28: 19
A29: =ROW()-8 -> 21 | C29: 送信データ削除区分 | D29: SND_DATA_DEL_KBN | E29: 半角数字 | F29: 1
A30: =ROW()-8 -> 22 | C30: 受信シーケンスNO | D30: RCV_SEQ_NO | E30: 半角英数字 | F30: 10
A31: =ROW()-8 -> 23 | C31: 処理受付番号 | D31: FUNC_UKETSUKE_NO | E31: 小数付き数値 | F31: 10 | G31: 0
A32: =ROW()-8 -> 24 | C32: 削除区分 | D32: DEL_KBN | E32: 半角数字 | F32: 1
A33: =ROW()-8 -> 25 | C33: 作成日時 | D33: CREATE_DT | E33: 全半角混在文字 | F33: 19
A34: =ROW()-8 -> 26 | C34: 作成ユーザ | D34: CREATE_USR | E34: 半角英数記号 | F34: 20
A35: =ROW()-8 -> 27 | C35: 作成処理 | D35: CREATE_FUNC | E35: 全半角混在文字 | F35: 64
A36: =ROW()-8 -> 28 | C36: 最新更新日時 | D36: NEW_UPDATE_DT | E36: 全半角混在文字 | F36: 19 | I36: システム日時(YYYY/MM/DD HH:MI:SS)
A37: =ROW()-8 -> 29 | C37: 最新更新ユーザ | D37: NEW_UPDATE_USR | E37: 半角英数記号 | F37: 20 | I37: "EDI"
A38: =ROW()-8 -> 30 | C38: 最新更新処理 | D38: NEW_UPDATE_FUNC | E38: 全半角混在文字 | F38: 64 | I38: "m_CMN_支払_データ抽出_010"
A39: =ROW()-8 -> 31 | C39: 更新回数 | D39: UPDATE_CNT | E39: 小数付き数値 | F39: 9 | G39: 0 | I39: 【更新回数】＋1

Sheet ３．項目転送（EDI採番マスタ）_更新
A6: ■ | B6: EDI採番マスタ 更新
A7: EDI採番マスタマッピング | H7: 設 定 値
A8: № | B8: 項目グループ | C8: 項 目 名（和名） | D8: 項 目 名（英名） | E8: 型 | F8: 桁数 | G8: 小数桁数 | H8: 単 純 転 送 | I8: 編 集 内 容
A9: =ROW()-8 -> 1 | C9: EDI_採番種別 | D9: EDI_SAIBAN_SBT | E9: 半角英数字 | F9: 2
A10: =ROW()-8 -> 2 | C10: EDI_採番取得キー | D10: EDI_SAIBAN_SHUTOKU_KEY | E10: 半角英数字 | F10: 10
A11: =ROW()-8 -> 3 | C11: 有効桁数 | D11: YUKO_KETA_SU | E11: 小数付き数値 | F11: 2 | G11: 0
A12: =ROW()-8 -> 4 | C12: EDI_連番 | D12: EDI_REMBAN | E12: 小数付き数値 | F12: 10 | G12: 0 | I12: 【EDI_連番】＋1
A13: =ROW()-8 -> 5 | C13: マスタ最終更新ユーザ | D13: MST_UPDATE_USR | E13: 半角数字 | F13: 5
A14: =ROW()-8 -> 6 | C14: マスタ最終更新日時 | D14: MST_UPDATE_DT | E14: 全半角混在文字 | F14: 19
A15: =ROW()-8 -> 7 | C15: 削除区分 | D15: DEL_KBN | E15: 半角数字 | F15: 1
A16: =ROW()-8 -> 8 | C16: 作成日時 | D16: CREATE_DT | E16: 全半角混在文字 | F16: 19
A17: =ROW()-8 -> 9 | C17: 作成ユーザ | D17: CREATE_USR | E17: 半角英数記号 | F17: 20
A18: =ROW()-8 -> 10 | C18: 作成処理 | D18: CREATE_FUNC | E18: 全半角混在文字 | F18: 64
A19: =ROW()-8 -> 11 | C19: 最新更新日時 | D19: NEW_UPDATE_DT | E19: 全半角混在文字 | F19: 19 | I19: システム日時(YYYY/MM/DD HH:MI:SS)
A20: =ROW()-8 -> 12 | C20: 最新更新ユーザ | D20: NEW_UPDATE_USR | E20: 半角英数記号 | F20: 20 | I20: "EDI"
A21: =ROW()-8 -> 13 | C21: 最新更新処理 | D21: NEW_UPDATE_FUNC | E21: 全半角混在文字 | F21: 64 | I21: "m_CMN_支払_データ抽出_010"
A22: =ROW()-8 -> 14 | C22: 更新回数 | D22: UPDATE_CNT | E22: 小数付き数値 | F22: 9 | G22: 0 | I22: 【更新回数】＋1

Sheet ４．項目転送（連携ファイル）
A6: ■ | B6: 連携ファイルマッピング仕様
A7: 連携ファイル | H7: 設 定 値
A8: № | B8: 項目グループ | C8: 項 目 名（和名） | D8: 項 目 名（英名） | E8: 型 | F8: 桁数 | G8: 小数桁数 | H8: 単 純 転 送 | I8: 編 集 内 容
A9: =ROW()-8 -> 1 | C9: 送信シーケンスNO | D9: SND_SEQ_NO | E9: 半角英数字 | F9: 10 | H9: 【EDI送信DB_支払.送信シーケンスNO】
A10: =ROW()-8 -> 2 | C10: データ交換ID | D10: DATA_KOKAN_ID | E10: 半角英数字 | F10: 6 | H10: 【EDI送信DB_支払.データ交換ID】
A11: =ROW()-8 -> 3 | C11: EDI_機能カテゴリコード | D11: EDI_KINO_CATEGORY_CD | E11: 半角英数字 | F11: 4 | H11: 【EDI送信DB_支払.EDI_機能カテゴリコード】
A12: =ROW()-8 -> 4 | C12: 仕入先コード | D12: SUP_CD | E12: 半角数字 | F12: 10 | H12: 【EDI送信DB_支払.仕入先コード】
A13: =ROW()-8 -> 5 | C13: 販区 | D13: HAN_KBN | E13: 半角英数字 | F13: 3 | H13: 【EDI送信DB_支払.販区】
A14: =ROW()-8 -> 6 | C14: 起算日 | D14: KISAN_D | E14: 半角英数字 | F14: 8 | H14: 【EDI送信DB_支払.起算日】
A15: =ROW()-8 -> 7 | C15: 金種 | D15: KINSHU | E15: 半角英字 | F15: 1 | H15: 【EDI送信DB_支払.金種】
A16: =ROW()-8 -> 8 | C16: 本支店コード | D16: HONSHITEN_CD | E16: 半角数字 | F16: 1 | H16: 【EDI送信DB_支払.本支店コード】
A17: =ROW()-8 -> 9 | C17: 締切年月日 | D17: SHIMEKIRI_YMD | E17: 日付(年月日) | F17: 8 | H17: 【EDI送信DB_支払.締切年月日】
A18: =ROW()-8 -> 10 | C18: 満期日 | D18: MANKI_D | E18: 半角英数字 | F18: 8 | H18: 【EDI送信DB_支払.満期日】
A19: =ROW()-8 -> 11 | C19: 銀行コード | D19: BANK_CD | E19: 半角数字 | F19: 4 | H19: 【EDI送信DB_支払.銀行コード】
A20: =ROW()-8 -> 12 | C20: 支店コード | D20: SHITEN_CD | E20: 半角数字 | F20: 3 | H20: 【EDI送信DB_支払.支店コード】
... A24: =ROW()-8 -> 16 | C24: 振込先口座NO | D24: FURIKOMI_KOZA_NO | E24: 半角英数字 | F24: 7 | H24: 【EDI送信DB_支払.振込先口座NO】
A25: =ROW()-8 -> 17 | C25: EDI_今回支払金額 | D25: EDI_KONKAI_PAY_GAKU | E25: 数値 | F25: 13 | G25: 0 | H25: 【EDI送信DB_支払.EDI_今回支払金額】
A26: =ROW()-8 -> 18 | C26: 支払年月日 | D26: PAY_YMD | E26: 日付(年月日) | F26: 8 | H26: 【EDI送信DB_支払.支払年月日】
A27: =ROW()-8 -> 19 | C27: 送信データ削除区分 | D27: SND_DATA_DEL_KBN | E27: 半角数字 | F27: 1 | H27: 【EDI送信DB_支払.送信データ削除区分】
A28: =ROW()-8 -> 20 | C28: 受信シーケンスNO | D28: RCV_SEQ_NO | E28: 半角英数字 | F28: 10 | H28: 【EDI送信DB_支払.受信シーケンスNO】
A29: =ROW()-8 -> 21 | C29: 処理受付番号 | D29: FUNC_UKETSUKE_NO | E29: 数値 | F29: 10 | G29: 0 | H29: 【EDI送信DB_支払.処理受付番号】
A30: =ROW()-8 -> 22 | C30: 削除区分 | D30: DEL_KBN | E30: 半角数字 | F30: 1 | H30: 【EDI送信DB_支払.削除区分】
A31: =ROW()-8 -> 23 | C31: 受信シーケンスNO_2 | D31: RCV_SEQ_NO_2 | E31: 半角文字 | F31: 10 | H31: 【EDI受信DB_仕入先.受信シーケンスNO】
A32: =ROW()-8 -> 24 | C32: 確定仕入責任組織コード(旧) | D32: CONFIRM_SIR_SKNIN_SSHK_CD_OLD | E32: 半角英数字 | F32: 5 | H32: 【EDI受信DB_仕入先.確定仕入責任組織コード(旧)】
A33: =ROW()-8 -> 25 | C33: JPCA_EDI請求金額 | D33: JPCA_EDI_SEIKYU_GAKU | E33: 数値 | F33: 13 | G33: 0 | H33: 【EDI受信DB_仕入先.JPCA_EDI請求金額】
A34: =ROW()-8 -> 26 | C34: 相手先別データ | D34: AITE_SAKI_BETSU_DATA | E34: 全半角混在 | F34: 4000 | H34: 【EDI受信DB_仕入先.相手先別データ】
A35: =ROW()-8 -> 27 | C35: 処理受付番号 | D35: FUNC_UKETSUKE_NO | E35: 数値 | F35: 10 | G35: 0 | H35: 【EDI採番マスタ.EDI_連番】

Sheet ５．【参考】項目転送取引先別一覧表
A1: 項目グループ | B1: 項 目 名（和名） | C1: 項 目 名（英名） | D1: 日本触媒 | E1: 三菱ケミカル | F1: 旭化成 | G1: 住友化学 | H1: 宇部興産 | I1: テクノUMG | J1: 日本PE・PP | K1: ユニチカ | L1: 東洋紡 | M1: 倉敷紡績 | N1: クラレ・クラﾄレ | O1: 備考
A2: EDI送信DB_支払 | B2: 送信シーケンスNO | C2: SND_SEQ_NO | D2: 〇 | E2: 〇 | F2: 〇 | G2: 〇 | H2: 〇 | I2: 〇 | J2: 〇 | K2: 〇 | L2: 〇 | M2: 〇 | N2: 〇 | O2: EDI送信DB_支払 のPKのため | P2: =COUNTIF(D2:N2,"〇")>=1 -> TRUE
A3: EDI送信DB_支払 | B3: データ交換ID | C3: DATA_KOKAN_ID | D3: 〇 | E3: 〇 | F3: 〇 | G3: 〇 | H3: 〇 | I3: 〇 | J3: 〇 | K3: 〇 | L3: 〇 | M3: 〇 | N3: 〇 | O3: 後のフローで使用するため、必須 | P3: =COUNTIF(D3:N3,"〇")>=1 -> TRUE
A4: EDI送信DB_支払 | B4: EDI_機能カテゴリコード | C4: EDI_KINO_CATEGORY_CD | N4: 〇 | O4: 後のフローで使用するため、必須 | P4: =COUNTIF(D4:N4,"〇")>=1 -> TRUE
A5: EDI送信DB_支払 | B5: 仕入先コード | C5: SUP_CD | D5: 〇 | E5: 〇 | G5: 〇 | H5: 〇 | I5: 〇 | J5: 〇 | K5: 〇 | L5: 〇 | M5: 〇 | N5: 〇 | O5: 後のフローで使用するため、必須 | P5: =COUNTIF(D5:N5,"〇")>=1 -> TRUE
A6: EDI送信DB_支払 | B6: 販区 | C6: HAN_KBN | N6: 〇 | O6: 後のフローで使用するため、必須 | P6: =COUNTIF(D6:N6,"〇")>=1 -> TRUE
A7: EDI送信DB_支払 | B7: 起算日 | C7: KISAN_D | N7: 〇 | O7: 後のフローで使用するため、必須 | P7: =COUNTIF(D7:N7,"〇")>=1 -> TRUE
A8: EDI送信DB_支払 | B8: 金種 | C8: KINSHU | D8: 〇 | E8: 〇 | G8: 〇 | H8: 〇 | I8: 〇 | J8: 〇 | K8: 〇 | N8: 〇 | O8: 後のフローで使用するため、必須 | P8: =COUNTIF(D8:N8,"〇")>=1 -> TRUE
A9: EDI送信DB_支払 | B9: 本支店コード | C9: HONSHITEN_CD | D9: 〇 | E9: 〇 | G9: 〇 | H9: 〇 | I9: 〇 | J9: 〇 | K9: 〇 | L9: 〇 | M9: 〇 | N9: 〇 | O9: 後のフローで使用するため、必須 | P9: =COUNTIF(D9:N9,"〇")>=1 -> TRUE
A10: EDI送信DB_支払 | B10: 締切年月日 | C10: SHIMEKIRI_YMD | N10: 〇 | O10: 後のフローで使用するため、必須 | P10: =COUNTIF(D10:N10,"〇")>=1 -> TRUE
A11: EDI送信DB_支払 | B11: 満期日 | C11: MANKI_D | D11: 〇 | E11: 〇 | H11: 〇 | J11: 〇 | K11: 〇 | L11: 〇 | M11: 〇 | N11: 〇 | O11: 後のフローで使用するため、必須 | P11: =COUNTIF(D11:N11,"〇")>=1 -> TRUE
A12: EDI送信DB_支払 | B12: 銀行コード | C12: BANK_CD | D12: 〇 | E12: 〇 | H12: 〇 | I12: 〇 | L12: 〇 | M12: 〇 | N12: 〇 | O12: 後のフローで使用するため、必須 | P12: =COUNTIF(D12:N12,"〇")>=1 -> TRUE
A13: EDI送信DB_支払 | B13: 支店コード | C13: SHITEN_CD | D13: 〇 | E13: 〇 | H13: 〇 | I13: 〇 | L13: 〇 | M13: 〇 | N13: 〇 | O13: 後のフローで使用するため、必須 | P13: =COUNTIF(D13:N13,"〇")>=1 -> TRUE
A14: EDI送信DB_支払 | B14: 銀行名(カナ) | C14: BANK_NMK | D14: 〇 | E14: 〇 | H14: 〇 | I14: 〇 | L14: 〇 | M14: 〇 | N14: 〇 | O14: 後のフローで使用するため、必須 | P14: =COUNTIF(D14:N14,"〇")>=1 -> TRUE
A15: EDI送信DB_支払 | B15: 支店名(カナ) | C15: SHITEN_NMK | D15: 〇 | E15: 〇 | H15: 〇 | I15: 〇 | L15: 〇 | M15: 〇 | N15: 〇 | O15: 後のフローで使用するため、必須 | P15: =COUNTIF(D15:N15,"〇")>=1 -> TRUE
A16: EDI送信DB_支払 | B16: 振込先口座種別 | C16: FURIKOMI_KOZA_SBT | N16: 〇 | O16: 後のフローで使用するため、必須 | P16: =COUNTIF(D16:N16,"〇")>=1 -> TRUE
A17: EDI送信DB_支払 | B17: 振込先口座NO | C17: FURIKOMI_KOZA_NO | E17: 〇 | N17: 〇 | O17: 後のフローで使用するため、必須 | P17: =COUNTIF(D17:N17,"〇")>=1 -> TRUE
A18: EDI送信DB_支払 | B18: EDI_今回支払金額 | C18: EDI_KONKAI_PAY_GAKU | D18: 〇 | E18: 〇 | F18: 〇 | G18: 〇 | H18: 〇 | I18: 〇 | J18: 〇 | K18: 〇 | L18: 〇 | M18: 〇 | N18: 〇 | O18: 後のフローで使用するため、必須 | P18: =COUNTIF(D18:N18,"〇")>=1 -> TRUE
A19: EDI送信DB_支払 | B19: 支払年月日 | C19: PAY_YMD | I19: 〇 | J19: 〇 | K19: 〇 | L19: 〇 | N19: 〇 | O19: 後のフローで使用するため、必須 | P19: =COUNTIF(D19:N19,"〇")>=1 -> TRUE
A20: EDI送信DB_支払 | B20: EDI_送信状況種別 | C20: EDI_TEKIYO_START_YMD | O20: 後のフローで使用するため、必須 | P20: =COUNTIF(D20:N20,"〇")>=1 -> FALSE
A21: EDI送信DB_支払 | B21: 送信日時 | C21: EDI_MK_TORIHIKI_KBN | O21: 後のフローで使用するため、必須 | P21: =COUNTIF(D21:N21,"〇")>=1 -> FALSE
A22: EDI送信DB_支払 | B22: 送信データ削除区分 | C22: EDI_MK_HACSHA_CD_SND | D22: 〇 | E22: 〇 | F22: 〇 | G22: 〇 | H22: 〇 | I22: 〇 | J22: 〇 | K22: 〇 | L22: 〇 | M22: 〇 | N22: 〇 | O22: 後のフローで使用するため、必須 | P22: =COUNTIF(D22:N22,"〇")>=1 -> TRUE
A23: EDI送信DB_支払 | B23: 受信シーケンスNO | C23: RCV_SEQ_NO | N23: 〇 | O23: 後のフローで使用するため、必須 | P23: =COUNTIF(D23:N23,"〇")>=1 -> TRUE
A24: EDI送信DB_支払 | B24: 処理受付番号 | C24: FUNC_UKETSUKE_NO | N24: 〇 | O24: 後のフローで使用するため、必須 | P24: =COUNTIF(D24:N24,"〇")>=1 -> TRUE
A25: 支払い・支払い明細 | B25: 削除区分 | C25: DEL_KBN | O25: 後のフローで使用するため、必須 | P25: =COUNTIF(D25:N25,"〇")>=1 -> FALSE
A26: 支払い・支払い明細 | B26: 作成日時 | C26: HAC_NO | O26: 後のフローで使用するため、必須 | P26: =COUNTIF(D26:N26,"〇")>=1 -> FALSE
A27: 支払い・支払い明細 | B27: 作成ユーザ | C27: HAC_GYO_NO | O27: 後のフローで使用するため、必須 | P27: =COUNTIF(D27:N27,"〇")>=1 -> FALSE
A28: 支払い・支払い明細 | B28: 作成処理 | C28: JUC_YMD | O28: 後のフローで使用するため、必須 | P28: =COUNTIF(D28:N28,"〇")>=1 -> FALSE
A29: 支払い・支払い明細 | B29: 最新更新日時 | C29: EDI_MK_JUC_NO | O29: 後のフローで使用するため、必須 | P29: =COUNTIF(D29:N29,"〇")>=1 -> FALSE
A30: 支払い・支払い明細 | B30: 最新更新ユーザ | C30: EDI_MK_JUC_GYO_NO | O30: 後のフローで使用するため、必須 | P30: =COUNTIF(D30:N30,"〇")>=1 -> FALSE
A31: 支払い・支払い明細 | B31: 最新更新処理 | C31: EDI_HAN_CHUMON_NO | O31: 後のフローで使用するため、必須 | P31: =COUNTIF(D31:N31,"〇")>=1 -> FALSE
A32: 支払い・支払い明細 | B32: 更新回数 | C32: EDI_MK_ATUKAITEN_CD | O32: 後のフローで使用するため、必須 | P32: =COUNTIF(D32:N32,"〇")>=1 -> FALSE
A33: 仕入先 | B33: 受信シーケンスNO | C33: RCV_SEQ_NO | D33: 〇 | E33: 〇 | F33: 〇 | G33: 〇 | H33: 〇 | I33: 〇 | J33: 〇 | K33: 〇 | L33: 〇 | M33: 〇 | N33: 〇 | O33: EDI受信DB_仕入先 のPKのため | P33: =COUNTIF(D33:N33,"〇")>=1 -> TRUE
A34: 仕入先 | B34: データ交換ID | C34: DATA_KOKAN_ID | P34: =COUNTIF(D34:N34,"〇")>=1 -> FALSE
A35: 仕入先 | B35: EDI_機能カテゴリコード | C35: EDI_KINO_CATEGORY_CD | P35: =COUNTIF(D35:N35,"〇")>=1 -> FALSE
A36: 仕入先 | B36: 販売先不明区分 | C36: HAN_FUMEI_KBN | P36: =COUNTIF(D36:N36,"〇")>=1 -> FALSE
A37: 仕入先 | B37: 販売先コード | C37: HAN_CD | P37: =COUNTIF(D37:N37,"〇")>=1 -> FALSE
A38: 仕入先 | B38: 販売先コード(確定) | C38: HAN_CD_KAKUTEI | P38: =COUNTIF(D38:N38,"〇")>=1 -> FALSE
A39: 仕入先 | B39: 受信時組織コード | C39: RCV_SOSHIKI_CD | P39: =COUNTIF(D39:N39,"〇")>=1 -> FALSE
A40: 仕入先 | B40: 受信時組織コード(確定) | C40: RCV_SOSHIKI_CD_KAKUTEI | P40: =COUNTIF(D40:N40,"〇")>=1 -> FALSE
...
